2024-09-24 17:35:42,491 [DEBUG] Response for getUpdates: [409] "'{"ok":false,"error_code":409,"description":"Conflict: terminated by other getUpdates request; make sure that only one bot instance is running"}'" aiogram
2024-09-24 17:35:42,491 [ERROR] Cause exception while getting updates. aiogram.dispatcher.dispatcher
Traceback (most recent call last):
  File "C:\Users\Malam\AppData\Local\Packages\PythonSoftwareFoundation.Python.3.11_qbz5n2kfra8p0\LocalCache\local-packages\Python311\site-packages\aiogram\dispatcher\dispatcher.py", line 381, in start_polling
    updates = await self.bot.get_updates(
              ^^^^^^^^^^^^^^^^^^^^^^^^^^^
  File "C:\Users\Malam\AppData\Local\Packages\PythonSoftwareFoundation.Python.3.11_qbz5n2kfra8p0\LocalCache\local-packages\Python311\site-packages\aiogram\bot\bot.py", line 110, in get_updates
    result = await self.request(api.Methods.GET_UPDATES, payload)
             ^^^^^^^^^^^^^^^^^^^^^^^^^^^^^^^^^^^^^^^^^^^^^^^^^^^^
  File "C:\Users\Malam\AppData\Local\Packages\PythonSoftwareFoundation.Python.3.11_qbz5n2kfra8p0\LocalCache\local-packages\Python311\site-packages\aiogram\bot\base.py", line 236, in request
    return await api.make_request(await self.get_session(), self.server, self.__token, method, data, files,
           ^^^^^^^^^^^^^^^^^^^^^^^^^^^^^^^^^^^^^^^^^^^^^^^^^^^^^^^^^^^^^^^^^^^^^^^^^^^^^^^^^^^^^^^^^^^^^^^^
  File "C:\Users\Malam\AppData\Local\Packages\PythonSoftwareFoundation.Python.3.11_qbz5n2kfra8p0\LocalCache\local-packages\Python311\site-packages\aiogram\bot\api.py", line 140, in make_request
    return check_result(method, response.content_type, response.status, await response.text())
           ^^^^^^^^^^^^^^^^^^^^^^^^^^^^^^^^^^^^^^^^^^^^^^^^^^^^^^^^^^^^^^^^^^^^^^^^^^^^^^^^^^^
  File "C:\Users\Malam\AppData\Local\Packages\PythonSoftwareFoundation.Python.3.11_qbz5n2kfra8p0\LocalCache\local-packages\Python311\site-packages\aiogram\bot\api.py", line 119, in check_result
    exceptions.ConflictError.detect(description)
  File "C:\Users\Malam\AppData\Local\Packages\PythonSoftwareFoundation.Python.3.11_qbz5n2kfra8p0\LocalCache\local-packages\Python311\site-packages\aiogram\utils\exceptions.py", line 140, in detect
    raise err(cls.text or description)
aiogram.utils.exceptions.TerminatedByOtherGetUpdates: Terminated by other getupdates request; make sure that only one bot instance is running
2024-09-24 17:35:47,495 [DEBUG] Make request: "getUpdates" with data: "{'offset': 106805196, 'timeout': 20}" and files "None" aiogram
2024-09-24 17:35:52,589 [DEBUG] Response for getUpdates: [409] "'{"ok":false,"error_code":409,"description":"Conflict: terminated by other getUpdates request; make sure that only one bot instance is running"}'" aiogram
2024-09-24 17:35:52,589 [ERROR] Cause exception while getting updates. aiogram.dispatcher.dispatcher
Traceback (most recent call last):
  File "C:\Users\Malam\AppData\Local\Packages\PythonSoftwareFoundation.Python.3.11_qbz5n2kfra8p0\LocalCache\local-packages\Python311\site-packages\aiogram\dispatcher\dispatcher.py", line 381, in start_polling
    updates = await self.bot.get_updates(
              ^^^^^^^^^^^^^^^^^^^^^^^^^^^
  File "C:\Users\Malam\AppData\Local\Packages\PythonSoftwareFoundation.Python.3.11_qbz5n2kfra8p0\LocalCache\local-packages\Python311\site-packages\aiogram\bot\bot.py", line 110, in get_updates
    result = await self.request(api.Methods.GET_UPDATES, payload)
             ^^^^^^^^^^^^^^^^^^^^^^^^^^^^^^^^^^^^^^^^^^^^^^^^^^^^
  File "C:\Users\Malam\AppData\Local\Packages\PythonSoftwareFoundation.Python.3.11_qbz5n2kfra8p0\LocalCache\local-packages\Python311\site-packages\aiogram\bot\base.py", line 236, in request
    return await api.make_request(await self.get_session(), self.server, self.__token, method, data, files,
           ^^^^^^^^^^^^^^^^^^^^^^^^^^^^^^^^^^^^^^^^^^^^^^^^^^^^^^^^^^^^^^^^^^^^^^^^^^^^^^^^^^^^^^^^^^^^^^^^
  File "C:\Users\Malam\AppData\Local\Packages\PythonSoftwareFoundation.Python.3.11_qbz5n2kfra8p0\LocalCache\local-packages\Python311\site-packages\aiogram\bot\api.py", line 140, in make_request
    return check_result(method, response.content_type, response.status, await response.text())
           ^^^^^^^^^^^^^^^^^^^^^^^^^^^^^^^^^^^^^^^^^^^^^^^^^^^^^^^^^^^^^^^^^^^^^^^^^^^^^^^^^^^
  File "C:\Users\Malam\AppData\Local\Packages\PythonSoftwareFoundation.Python.3.11_qbz5n2kfra8p0\LocalCache\local-packages\Python311\site-packages\aiogram\bot\api.py", line 119, in check_result
    exceptions.ConflictError.detect(description)
  File "C:\Users\Malam\AppData\Local\Packages\PythonSoftwareFoundation.Python.3.11_qbz5n2kfra8p0\LocalCache\local-packages\Python311\site-packages\aiogram\utils\exceptions.py", line 140, in detect
    raise err(cls.text or description)
aiogram.utils.exceptions.TerminatedByOtherGetUpdates: Terminated by other getupdates request; make sure that only one bot instance is running
2024-09-24 17:35:57,599 [DEBUG] Make request: "getUpdates" with data: "{'offset': 106805196, 'timeout': 20}" and files "None" aiogram
2024-09-24 17:36:02,678 [DEBUG] Response for getUpdates: [409] "'{"ok":false,"error_code":409,"description":"Conflict: terminated by other getUpdates request; make sure that only one bot instance is running"}'" aiogram
2024-09-24 17:36:02,678 [ERROR] Cause exception while getting updates. aiogram.dispatcher.dispatcher
Traceback (most recent call last):
  File "C:\Users\Malam\AppData\Local\Packages\PythonSoftwareFoundation.Python.3.11_qbz5n2kfra8p0\LocalCache\local-packages\Python311\site-packages\aiogram\dispatcher\dispatcher.py", line 381, in start_polling
    updates = await self.bot.get_updates(
              ^^^^^^^^^^^^^^^^^^^^^^^^^^^
  File "C:\Users\Malam\AppData\Local\Packages\PythonSoftwareFoundation.Python.3.11_qbz5n2kfra8p0\LocalCache\local-packages\Python311\site-packages\aiogram\bot\bot.py", line 110, in get_updates
    result = await self.request(api.Methods.GET_UPDATES, payload)
             ^^^^^^^^^^^^^^^^^^^^^^^^^^^^^^^^^^^^^^^^^^^^^^^^^^^^
  File "C:\Users\Malam\AppData\Local\Packages\PythonSoftwareFoundation.Python.3.11_qbz5n2kfra8p0\LocalCache\local-packages\Python311\site-packages\aiogram\bot\base.py", line 236, in request
    return await api.make_request(await self.get_session(), self.server, self.__token, method, data, files,
           ^^^^^^^^^^^^^^^^^^^^^^^^^^^^^^^^^^^^^^^^^^^^^^^^^^^^^^^^^^^^^^^^^^^^^^^^^^^^^^^^^^^^^^^^^^^^^^^^
  File "C:\Users\Malam\AppData\Local\Packages\PythonSoftwareFoundation.Python.3.11_qbz5n2kfra8p0\LocalCache\local-packages\Python311\site-packages\aiogram\bot\api.py", line 140, in make_request
    return check_result(method, response.content_type, response.status, await response.text())
           ^^^^^^^^^^^^^^^^^^^^^^^^^^^^^^^^^^^^^^^^^^^^^^^^^^^^^^^^^^^^^^^^^^^^^^^^^^^^^^^^^^^
  File "C:\Users\Malam\AppData\Local\Packages\PythonSoftwareFoundation.Python.3.11_qbz5n2kfra8p0\LocalCache\local-packages\Python311\site-packages\aiogram\bot\api.py", line 119, in check_result
    exceptions.ConflictError.detect(description)
  File "C:\Users\Malam\AppData\Local\Packages\PythonSoftwareFoundation.Python.3.11_qbz5n2kfra8p0\LocalCache\local-packages\Python311\site-packages\aiogram\utils\exceptions.py", line 140, in detect
    raise err(cls.text or description)
aiogram.utils.exceptions.TerminatedByOtherGetUpdates: Terminated by other getupdates request; make sure that only one bot instance is running
2024-09-24 17:36:07,691 [DEBUG] Make request: "getUpdates" with data: "{'offset': 106805196, 'timeout': 20}" and files "None" aiogram
2024-09-24 17:36:12,792 [DEBUG] Response for getUpdates: [409] "'{"ok":false,"error_code":409,"description":"Conflict: terminated by other getUpdates request; make sure that only one bot instance is running"}'" aiogram
2024-09-24 17:36:12,792 [ERROR] Cause exception while getting updates. aiogram.dispatcher.dispatcher
Traceback (most recent call last):
  File "C:\Users\Malam\AppData\Local\Packages\PythonSoftwareFoundation.Python.3.11_qbz5n2kfra8p0\LocalCache\local-packages\Python311\site-packages\aiogram\dispatcher\dispatcher.py", line 381, in start_polling
    updates = await self.bot.get_updates(
              ^^^^^^^^^^^^^^^^^^^^^^^^^^^
  File "C:\Users\Malam\AppData\Local\Packages\PythonSoftwareFoundation.Python.3.11_qbz5n2kfra8p0\LocalCache\local-packages\Python311\site-packages\aiogram\bot\bot.py", line 110, in get_updates
    result = await self.request(api.Methods.GET_UPDATES, payload)
             ^^^^^^^^^^^^^^^^^^^^^^^^^^^^^^^^^^^^^^^^^^^^^^^^^^^^
  File "C:\Users\Malam\AppData\Local\Packages\PythonSoftwareFoundation.Python.3.11_qbz5n2kfra8p0\LocalCache\local-packages\Python311\site-packages\aiogram\bot\base.py", line 236, in request
    return await api.make_request(await self.get_session(), self.server, self.__token, method, data, files,
           ^^^^^^^^^^^^^^^^^^^^^^^^^^^^^^^^^^^^^^^^^^^^^^^^^^^^^^^^^^^^^^^^^^^^^^^^^^^^^^^^^^^^^^^^^^^^^^^^
  File "C:\Users\Malam\AppData\Local\Packages\PythonSoftwareFoundation.Python.3.11_qbz5n2kfra8p0\LocalCache\local-packages\Python311\site-packages\aiogram\bot\api.py", line 140, in make_request
    return check_result(method, response.content_type, response.status, await response.text())
           ^^^^^^^^^^^^^^^^^^^^^^^^^^^^^^^^^^^^^^^^^^^^^^^^^^^^^^^^^^^^^^^^^^^^^^^^^^^^^^^^^^^
  File "C:\Users\Malam\AppData\Local\Packages\PythonSoftwareFoundation.Python.3.11_qbz5n2kfra8p0\LocalCache\local-packages\Python311\site-packages\aiogram\bot\api.py", line 119, in check_result
    exceptions.ConflictError.detect(description)
  File "C:\Users\Malam\AppData\Local\Packages\PythonSoftwareFoundation.Python.3.11_qbz5n2kfra8p0\LocalCache\local-packages\Python311\site-packages\aiogram\utils\exceptions.py", line 140, in detect
    raise err(cls.text or description)
aiogram.utils.exceptions.TerminatedByOtherGetUpdates: Terminated by other getupdates request; make sure that only one bot instance is running
2024-09-24 17:36:17,810 [DEBUG] Make request: "getUpdates" with data: "{'offset': 106805196, 'timeout': 20}" and files "None" aiogram
2024-09-24 17:36:22,912 [DEBUG] Response for getUpdates: [409] "'{"ok":false,"error_code":409,"description":"Conflict: terminated by other getUpdates request; make sure that only one bot instance is running"}'" aiogram
2024-09-24 17:36:22,913 [ERROR] Cause exception while getting updates. aiogram.dispatcher.dispatcher
Traceback (most recent call last):
  File "C:\Users\Malam\AppData\Local\Packages\PythonSoftwareFoundation.Python.3.11_qbz5n2kfra8p0\LocalCache\local-packages\Python311\site-packages\aiogram\dispatcher\dispatcher.py", line 381, in start_polling
    updates = await self.bot.get_updates(
              ^^^^^^^^^^^^^^^^^^^^^^^^^^^
  File "C:\Users\Malam\AppData\Local\Packages\PythonSoftwareFoundation.Python.3.11_qbz5n2kfra8p0\LocalCache\local-packages\Python311\site-packages\aiogram\bot\bot.py", line 110, in get_updates
    result = await self.request(api.Methods.GET_UPDATES, payload)
             ^^^^^^^^^^^^^^^^^^^^^^^^^^^^^^^^^^^^^^^^^^^^^^^^^^^^
  File "C:\Users\Malam\AppData\Local\Packages\PythonSoftwareFoundation.Python.3.11_qbz5n2kfra8p0\LocalCache\local-packages\Python311\site-packages\aiogram\bot\base.py", line 236, in request
    return await api.make_request(await self.get_session(), self.server, self.__token, method, data, files,
           ^^^^^^^^^^^^^^^^^^^^^^^^^^^^^^^^^^^^^^^^^^^^^^^^^^^^^^^^^^^^^^^^^^^^^^^^^^^^^^^^^^^^^^^^^^^^^^^^
  File "C:\Users\Malam\AppData\Local\Packages\PythonSoftwareFoundation.Python.3.11_qbz5n2kfra8p0\LocalCache\local-packages\Python311\site-packages\aiogram\bot\api.py", line 140, in make_request
    return check_result(method, response.content_type, response.status, await response.text())
           ^^^^^^^^^^^^^^^^^^^^^^^^^^^^^^^^^^^^^^^^^^^^^^^^^^^^^^^^^^^^^^^^^^^^^^^^^^^^^^^^^^^
  File "C:\Users\Malam\AppData\Local\Packages\PythonSoftwareFoundation.Python.3.11_qbz5n2kfra8p0\LocalCache\local-packages\Python311\site-packages\aiogram\bot\api.py", line 119, in check_result
    exceptions.ConflictError.detect(description)
  File "C:\Users\Malam\AppData\Local\Packages\PythonSoftwareFoundation.Python.3.11_qbz5n2kfra8p0\LocalCache\local-packages\Python311\site-packages\aiogram\utils\exceptions.py", line 140, in detect
    raise err(cls.text or description)
aiogram.utils.exceptions.TerminatedByOtherGetUpdates: Terminated by other getupdates request; make sure that only one bot instance is running
2024-09-24 17:36:27,927 [DEBUG] Make request: "getUpdates" with data: "{'offset': 106805196, 'timeout': 20}" and files "None" aiogram
2024-09-24 17:36:33,025 [DEBUG] Response for getUpdates: [409] "'{"ok":false,"error_code":409,"description":"Conflict: terminated by other getUpdates request; make sure that only one bot instance is running"}'" aiogram
2024-09-24 17:36:33,026 [ERROR] Cause exception while getting updates. aiogram.dispatcher.dispatcher
Traceback (most recent call last):
  File "C:\Users\Malam\AppData\Local\Packages\PythonSoftwareFoundation.Python.3.11_qbz5n2kfra8p0\LocalCache\local-packages\Python311\site-packages\aiogram\dispatcher\dispatcher.py", line 381, in start_polling
    updates = await self.bot.get_updates(
              ^^^^^^^^^^^^^^^^^^^^^^^^^^^
  File "C:\Users\Malam\AppData\Local\Packages\PythonSoftwareFoundation.Python.3.11_qbz5n2kfra8p0\LocalCache\local-packages\Python311\site-packages\aiogram\bot\bot.py", line 110, in get_updates
    result = await self.request(api.Methods.GET_UPDATES, payload)
             ^^^^^^^^^^^^^^^^^^^^^^^^^^^^^^^^^^^^^^^^^^^^^^^^^^^^
  File "C:\Users\Malam\AppData\Local\Packages\PythonSoftwareFoundation.Python.3.11_qbz5n2kfra8p0\LocalCache\local-packages\Python311\site-packages\aiogram\bot\base.py", line 236, in request
    return await api.make_request(await self.get_session(), self.server, self.__token, method, data, files,
           ^^^^^^^^^^^^^^^^^^^^^^^^^^^^^^^^^^^^^^^^^^^^^^^^^^^^^^^^^^^^^^^^^^^^^^^^^^^^^^^^^^^^^^^^^^^^^^^^
  File "C:\Users\Malam\AppData\Local\Packages\PythonSoftwareFoundation.Python.3.11_qbz5n2kfra8p0\LocalCache\local-packages\Python311\site-packages\aiogram\bot\api.py", line 140, in make_request
    return check_result(method, response.content_type, response.status, await response.text())
           ^^^^^^^^^^^^^^^^^^^^^^^^^^^^^^^^^^^^^^^^^^^^^^^^^^^^^^^^^^^^^^^^^^^^^^^^^^^^^^^^^^^
  File "C:\Users\Malam\AppData\Local\Packages\PythonSoftwareFoundation.Python.3.11_qbz5n2kfra8p0\LocalCache\local-packages\Python311\site-packages\aiogram\bot\api.py", line 119, in check_result
    exceptions.ConflictError.detect(description)
  File "C:\Users\Malam\AppData\Local\Packages\PythonSoftwareFoundation.Python.3.11_qbz5n2kfra8p0\LocalCache\local-packages\Python311\site-packages\aiogram\utils\exceptions.py", line 140, in detect
    raise err(cls.text or description)
aiogram.utils.exceptions.TerminatedByOtherGetUpdates: Terminated by other getupdates request; make sure that only one bot instance is running
2024-09-24 17:36:38,039 [DEBUG] Make request: "getUpdates" with data: "{'offset': 106805196, 'timeout': 20}" and files "None" aiogram
2024-09-24 17:36:43,172 [DEBUG] Response for getUpdates: [409] "'{"ok":false,"error_code":409,"description":"Conflict: terminated by other getUpdates request; make sure that only one bot instance is running"}'" aiogram
2024-09-24 17:36:43,173 [ERROR] Cause exception while getting updates. aiogram.dispatcher.dispatcher
Traceback (most recent call last):
  File "C:\Users\Malam\AppData\Local\Packages\PythonSoftwareFoundation.Python.3.11_qbz5n2kfra8p0\LocalCache\local-packages\Python311\site-packages\aiogram\dispatcher\dispatcher.py", line 381, in start_polling
    updates = await self.bot.get_updates(
              ^^^^^^^^^^^^^^^^^^^^^^^^^^^
  File "C:\Users\Malam\AppData\Local\Packages\PythonSoftwareFoundation.Python.3.11_qbz5n2kfra8p0\LocalCache\local-packages\Python311\site-packages\aiogram\bot\bot.py", line 110, in get_updates
    result = await self.request(api.Methods.GET_UPDATES, payload)
             ^^^^^^^^^^^^^^^^^^^^^^^^^^^^^^^^^^^^^^^^^^^^^^^^^^^^
  File "C:\Users\Malam\AppData\Local\Packages\PythonSoftwareFoundation.Python.3.11_qbz5n2kfra8p0\LocalCache\local-packages\Python311\site-packages\aiogram\bot\base.py", line 236, in request
    return await api.make_request(await self.get_session(), self.server, self.__token, method, data, files,
           ^^^^^^^^^^^^^^^^^^^^^^^^^^^^^^^^^^^^^^^^^^^^^^^^^^^^^^^^^^^^^^^^^^^^^^^^^^^^^^^^^^^^^^^^^^^^^^^^
  File "C:\Users\Malam\AppData\Local\Packages\PythonSoftwareFoundation.Python.3.11_qbz5n2kfra8p0\LocalCache\local-packages\Python311\site-packages\aiogram\bot\api.py", line 140, in make_request
    return check_result(method, response.content_type, response.status, await response.text())
           ^^^^^^^^^^^^^^^^^^^^^^^^^^^^^^^^^^^^^^^^^^^^^^^^^^^^^^^^^^^^^^^^^^^^^^^^^^^^^^^^^^^
  File "C:\Users\Malam\AppData\Local\Packages\PythonSoftwareFoundation.Python.3.11_qbz5n2kfra8p0\LocalCache\local-packages\Python311\site-packages\aiogram\bot\api.py", line 119, in check_result
    exceptions.ConflictError.detect(description)
  File "C:\Users\Malam\AppData\Local\Packages\PythonSoftwareFoundation.Python.3.11_qbz5n2kfra8p0\LocalCache\local-packages\Python311\site-packages\aiogram\utils\exceptions.py", line 140, in detect
    raise err(cls.text or description)
aiogram.utils.exceptions.TerminatedByOtherGetUpdates: Terminated by other getupdates request; make sure that only one bot instance is running
2024-09-24 17:36:48,189 [DEBUG] Make request: "getUpdates" with data: "{'offset': 106805196, 'timeout': 20}" and files "None" aiogram
2024-09-24 17:36:53,253 [DEBUG] Response for getUpdates: [409] "'{"ok":false,"error_code":409,"description":"Conflict: terminated by other getUpdates request; make sure that only one bot instance is running"}'" aiogram
2024-09-24 17:36:53,254 [ERROR] Cause exception while getting updates. aiogram.dispatcher.dispatcher
Traceback (most recent call last):
  File "C:\Users\Malam\AppData\Local\Packages\PythonSoftwareFoundation.Python.3.11_qbz5n2kfra8p0\LocalCache\local-packages\Python311\site-packages\aiogram\dispatcher\dispatcher.py", line 381, in start_polling
    updates = await self.bot.get_updates(
              ^^^^^^^^^^^^^^^^^^^^^^^^^^^
  File "C:\Users\Malam\AppData\Local\Packages\PythonSoftwareFoundation.Python.3.11_qbz5n2kfra8p0\LocalCache\local-packages\Python311\site-packages\aiogram\bot\bot.py", line 110, in get_updates
    result = await self.request(api.Methods.GET_UPDATES, payload)
             ^^^^^^^^^^^^^^^^^^^^^^^^^^^^^^^^^^^^^^^^^^^^^^^^^^^^
  File "C:\Users\Malam\AppData\Local\Packages\PythonSoftwareFoundation.Python.3.11_qbz5n2kfra8p0\LocalCache\local-packages\Python311\site-packages\aiogram\bot\base.py", line 236, in request
    return await api.make_request(await self.get_session(), self.server, self.__token, method, data, files,
           ^^^^^^^^^^^^^^^^^^^^^^^^^^^^^^^^^^^^^^^^^^^^^^^^^^^^^^^^^^^^^^^^^^^^^^^^^^^^^^^^^^^^^^^^^^^^^^^^
  File "C:\Users\Malam\AppData\Local\Packages\PythonSoftwareFoundation.Python.3.11_qbz5n2kfra8p0\LocalCache\local-packages\Python311\site-packages\aiogram\bot\api.py", line 140, in make_request
    return check_result(method, response.content_type, response.status, await response.text())
           ^^^^^^^^^^^^^^^^^^^^^^^^^^^^^^^^^^^^^^^^^^^^^^^^^^^^^^^^^^^^^^^^^^^^^^^^^^^^^^^^^^^
  File "C:\Users\Malam\AppData\Local\Packages\PythonSoftwareFoundation.Python.3.11_qbz5n2kfra8p0\LocalCache\local-packages\Python311\site-packages\aiogram\bot\api.py", line 119, in check_result
    exceptions.ConflictError.detect(description)
  File "C:\Users\Malam\AppData\Local\Packages\PythonSoftwareFoundation.Python.3.11_qbz5n2kfra8p0\LocalCache\local-packages\Python311\site-packages\aiogram\utils\exceptions.py", line 140, in detect
    raise err(cls.text or description)
aiogram.utils.exceptions.TerminatedByOtherGetUpdates: Terminated by other getupdates request; make sure that only one bot instance is running
2024-09-24 17:36:58,261 [DEBUG] Make request: "getUpdates" with data: "{'offset': 106805196, 'timeout': 20}" and files "None" aiogram
2024-09-24 17:37:03,380 [DEBUG] Response for getUpdates: [409] "'{"ok":false,"error_code":409,"description":"Conflict: terminated by other getUpdates request; make sure that only one bot instance is running"}'" aiogram
2024-09-24 17:37:03,380 [ERROR] Cause exception while getting updates. aiogram.dispatcher.dispatcher
Traceback (most recent call last):
  File "C:\Users\Malam\AppData\Local\Packages\PythonSoftwareFoundation.Python.3.11_qbz5n2kfra8p0\LocalCache\local-packages\Python311\site-packages\aiogram\dispatcher\dispatcher.py", line 381, in start_polling
    updates = await self.bot.get_updates(
              ^^^^^^^^^^^^^^^^^^^^^^^^^^^
  File "C:\Users\Malam\AppData\Local\Packages\PythonSoftwareFoundation.Python.3.11_qbz5n2kfra8p0\LocalCache\local-packages\Python311\site-packages\aiogram\bot\bot.py", line 110, in get_updates
    result = await self.request(api.Methods.GET_UPDATES, payload)
             ^^^^^^^^^^^^^^^^^^^^^^^^^^^^^^^^^^^^^^^^^^^^^^^^^^^^
  File "C:\Users\Malam\AppData\Local\Packages\PythonSoftwareFoundation.Python.3.11_qbz5n2kfra8p0\LocalCache\local-packages\Python311\site-packages\aiogram\bot\base.py", line 236, in request
    return await api.make_request(await self.get_session(), self.server, self.__token, method, data, files,
           ^^^^^^^^^^^^^^^^^^^^^^^^^^^^^^^^^^^^^^^^^^^^^^^^^^^^^^^^^^^^^^^^^^^^^^^^^^^^^^^^^^^^^^^^^^^^^^^^
  File "C:\Users\Malam\AppData\Local\Packages\PythonSoftwareFoundation.Python.3.11_qbz5n2kfra8p0\LocalCache\local-packages\Python311\site-packages\aiogram\bot\api.py", line 140, in make_request
    return check_result(method, response.content_type, response.status, await response.text())
           ^^^^^^^^^^^^^^^^^^^^^^^^^^^^^^^^^^^^^^^^^^^^^^^^^^^^^^^^^^^^^^^^^^^^^^^^^^^^^^^^^^^
  File "C:\Users\Malam\AppData\Local\Packages\PythonSoftwareFoundation.Python.3.11_qbz5n2kfra8p0\LocalCache\local-packages\Python311\site-packages\aiogram\bot\api.py", line 119, in check_result
    exceptions.ConflictError.detect(description)
  File "C:\Users\Malam\AppData\Local\Packages\PythonSoftwareFoundation.Python.3.11_qbz5n2kfra8p0\LocalCache\local-packages\Python311\site-packages\aiogram\utils\exceptions.py", line 140, in detect
    raise err(cls.text or description)
aiogram.utils.exceptions.TerminatedByOtherGetUpdates: Terminated by other getupdates request; make sure that only one bot instance is running
2024-09-24 17:37:08,395 [DEBUG] Make request: "getUpdates" with data: "{'offset': 106805196, 'timeout': 20}" and files "None" aiogram
2024-09-24 17:37:13,547 [DEBUG] Response for getUpdates: [409] "'{"ok":false,"error_code":409,"description":"Conflict: terminated by other getUpdates request; make sure that only one bot instance is running"}'" aiogram
2024-09-24 17:37:13,549 [ERROR] Cause exception while getting updates. aiogram.dispatcher.dispatcher
Traceback (most recent call last):
  File "C:\Users\Malam\AppData\Local\Packages\PythonSoftwareFoundation.Python.3.11_qbz5n2kfra8p0\LocalCache\local-packages\Python311\site-packages\aiogram\dispatcher\dispatcher.py", line 381, in start_polling
    updates = await self.bot.get_updates(
              ^^^^^^^^^^^^^^^^^^^^^^^^^^^
  File "C:\Users\Malam\AppData\Local\Packages\PythonSoftwareFoundation.Python.3.11_qbz5n2kfra8p0\LocalCache\local-packages\Python311\site-packages\aiogram\bot\bot.py", line 110, in get_updates
    result = await self.request(api.Methods.GET_UPDATES, payload)
             ^^^^^^^^^^^^^^^^^^^^^^^^^^^^^^^^^^^^^^^^^^^^^^^^^^^^
  File "C:\Users\Malam\AppData\Local\Packages\PythonSoftwareFoundation.Python.3.11_qbz5n2kfra8p0\LocalCache\local-packages\Python311\site-packages\aiogram\bot\base.py", line 236, in request
    return await api.make_request(await self.get_session(), self.server, self.__token, method, data, files,
           ^^^^^^^^^^^^^^^^^^^^^^^^^^^^^^^^^^^^^^^^^^^^^^^^^^^^^^^^^^^^^^^^^^^^^^^^^^^^^^^^^^^^^^^^^^^^^^^^
  File "C:\Users\Malam\AppData\Local\Packages\PythonSoftwareFoundation.Python.3.11_qbz5n2kfra8p0\LocalCache\local-packages\Python311\site-packages\aiogram\bot\api.py", line 140, in make_request
    return check_result(method, response.content_type, response.status, await response.text())
           ^^^^^^^^^^^^^^^^^^^^^^^^^^^^^^^^^^^^^^^^^^^^^^^^^^^^^^^^^^^^^^^^^^^^^^^^^^^^^^^^^^^
  File "C:\Users\Malam\AppData\Local\Packages\PythonSoftwareFoundation.Python.3.11_qbz5n2kfra8p0\LocalCache\local-packages\Python311\site-packages\aiogram\bot\api.py", line 119, in check_result
    exceptions.ConflictError.detect(description)
  File "C:\Users\Malam\AppData\Local\Packages\PythonSoftwareFoundation.Python.3.11_qbz5n2kfra8p0\LocalCache\local-packages\Python311\site-packages\aiogram\utils\exceptions.py", line 140, in detect
    raise err(cls.text or description)
aiogram.utils.exceptions.TerminatedByOtherGetUpdates: Terminated by other getupdates request; make sure that only one bot instance is running
2024-09-24 17:37:18,563 [DEBUG] Make request: "getUpdates" with data: "{'offset': 106805196, 'timeout': 20}" and files "None" aiogram
2024-09-24 17:37:23,648 [DEBUG] Response for getUpdates: [409] "'{"ok":false,"error_code":409,"description":"Conflict: terminated by other getUpdates request; make sure that only one bot instance is running"}'" aiogram
2024-09-24 17:37:23,649 [ERROR] Cause exception while getting updates. aiogram.dispatcher.dispatcher
Traceback (most recent call last):
  File "C:\Users\Malam\AppData\Local\Packages\PythonSoftwareFoundation.Python.3.11_qbz5n2kfra8p0\LocalCache\local-packages\Python311\site-packages\aiogram\dispatcher\dispatcher.py", line 381, in start_polling
    updates = await self.bot.get_updates(
              ^^^^^^^^^^^^^^^^^^^^^^^^^^^
  File "C:\Users\Malam\AppData\Local\Packages\PythonSoftwareFoundation.Python.3.11_qbz5n2kfra8p0\LocalCache\local-packages\Python311\site-packages\aiogram\bot\bot.py", line 110, in get_updates
    result = await self.request(api.Methods.GET_UPDATES, payload)
             ^^^^^^^^^^^^^^^^^^^^^^^^^^^^^^^^^^^^^^^^^^^^^^^^^^^^
  File "C:\Users\Malam\AppData\Local\Packages\PythonSoftwareFoundation.Python.3.11_qbz5n2kfra8p0\LocalCache\local-packages\Python311\site-packages\aiogram\bot\base.py", line 236, in request
    return await api.make_request(await self.get_session(), self.server, self.__token, method, data, files,
           ^^^^^^^^^^^^^^^^^^^^^^^^^^^^^^^^^^^^^^^^^^^^^^^^^^^^^^^^^^^^^^^^^^^^^^^^^^^^^^^^^^^^^^^^^^^^^^^^
  File "C:\Users\Malam\AppData\Local\Packages\PythonSoftwareFoundation.Python.3.11_qbz5n2kfra8p0\LocalCache\local-packages\Python311\site-packages\aiogram\bot\api.py", line 140, in make_request
    return check_result(method, response.content_type, response.status, await response.text())
           ^^^^^^^^^^^^^^^^^^^^^^^^^^^^^^^^^^^^^^^^^^^^^^^^^^^^^^^^^^^^^^^^^^^^^^^^^^^^^^^^^^^
  File "C:\Users\Malam\AppData\Local\Packages\PythonSoftwareFoundation.Python.3.11_qbz5n2kfra8p0\LocalCache\local-packages\Python311\site-packages\aiogram\bot\api.py", line 119, in check_result
    exceptions.ConflictError.detect(description)
  File "C:\Users\Malam\AppData\Local\Packages\PythonSoftwareFoundation.Python.3.11_qbz5n2kfra8p0\LocalCache\local-packages\Python311\site-packages\aiogram\utils\exceptions.py", line 140, in detect
    raise err(cls.text or description)
aiogram.utils.exceptions.TerminatedByOtherGetUpdates: Terminated by other getupdates request; make sure that only one bot instance is running
2024-09-24 17:37:28,653 [DEBUG] Make request: "getUpdates" with data: "{'offset': 106805196, 'timeout': 20}" and files "None" aiogram
2024-09-24 17:37:33,779 [DEBUG] Response for getUpdates: [409] "'{"ok":false,"error_code":409,"description":"Conflict: terminated by other getUpdates request; make sure that only one bot instance is running"}'" aiogram
2024-09-24 17:37:33,780 [ERROR] Cause exception while getting updates. aiogram.dispatcher.dispatcher
Traceback (most recent call last):
  File "C:\Users\Malam\AppData\Local\Packages\PythonSoftwareFoundation.Python.3.11_qbz5n2kfra8p0\LocalCache\local-packages\Python311\site-packages\aiogram\dispatcher\dispatcher.py", line 381, in start_polling
    updates = await self.bot.get_updates(
              ^^^^^^^^^^^^^^^^^^^^^^^^^^^
  File "C:\Users\Malam\AppData\Local\Packages\PythonSoftwareFoundation.Python.3.11_qbz5n2kfra8p0\LocalCache\local-packages\Python311\site-packages\aiogram\bot\bot.py", line 110, in get_updates
    result = await self.request(api.Methods.GET_UPDATES, payload)
             ^^^^^^^^^^^^^^^^^^^^^^^^^^^^^^^^^^^^^^^^^^^^^^^^^^^^
  File "C:\Users\Malam\AppData\Local\Packages\PythonSoftwareFoundation.Python.3.11_qbz5n2kfra8p0\LocalCache\local-packages\Python311\site-packages\aiogram\bot\base.py", line 236, in request
    return await api.make_request(await self.get_session(), self.server, self.__token, method, data, files,
           ^^^^^^^^^^^^^^^^^^^^^^^^^^^^^^^^^^^^^^^^^^^^^^^^^^^^^^^^^^^^^^^^^^^^^^^^^^^^^^^^^^^^^^^^^^^^^^^^
  File "C:\Users\Malam\AppData\Local\Packages\PythonSoftwareFoundation.Python.3.11_qbz5n2kfra8p0\LocalCache\local-packages\Python311\site-packages\aiogram\bot\api.py", line 140, in make_request
    return check_result(method, response.content_type, response.status, await response.text())
           ^^^^^^^^^^^^^^^^^^^^^^^^^^^^^^^^^^^^^^^^^^^^^^^^^^^^^^^^^^^^^^^^^^^^^^^^^^^^^^^^^^^
  File "C:\Users\Malam\AppData\Local\Packages\PythonSoftwareFoundation.Python.3.11_qbz5n2kfra8p0\LocalCache\local-packages\Python311\site-packages\aiogram\bot\api.py", line 119, in check_result
    exceptions.ConflictError.detect(description)
  File "C:\Users\Malam\AppData\Local\Packages\PythonSoftwareFoundation.Python.3.11_qbz5n2kfra8p0\LocalCache\local-packages\Python311\site-packages\aiogram\utils\exceptions.py", line 140, in detect
    raise err(cls.text or description)
aiogram.utils.exceptions.TerminatedByOtherGetUpdates: Terminated by other getupdates request; make sure that only one bot instance is running
2024-09-24 17:37:38,795 [DEBUG] Make request: "getUpdates" with data: "{'offset': 106805196, 'timeout': 20}" and files "None" aiogram
2024-09-24 17:37:43,872 [DEBUG] Response for getUpdates: [409] "'{"ok":false,"error_code":409,"description":"Conflict: terminated by other getUpdates request; make sure that only one bot instance is running"}'" aiogram
2024-09-24 17:37:43,873 [ERROR] Cause exception while getting updates. aiogram.dispatcher.dispatcher
Traceback (most recent call last):
  File "C:\Users\Malam\AppData\Local\Packages\PythonSoftwareFoundation.Python.3.11_qbz5n2kfra8p0\LocalCache\local-packages\Python311\site-packages\aiogram\dispatcher\dispatcher.py", line 381, in start_polling
    updates = await self.bot.get_updates(
              ^^^^^^^^^^^^^^^^^^^^^^^^^^^
  File "C:\Users\Malam\AppData\Local\Packages\PythonSoftwareFoundation.Python.3.11_qbz5n2kfra8p0\LocalCache\local-packages\Python311\site-packages\aiogram\bot\bot.py", line 110, in get_updates
    result = await self.request(api.Methods.GET_UPDATES, payload)
             ^^^^^^^^^^^^^^^^^^^^^^^^^^^^^^^^^^^^^^^^^^^^^^^^^^^^
  File "C:\Users\Malam\AppData\Local\Packages\PythonSoftwareFoundation.Python.3.11_qbz5n2kfra8p0\LocalCache\local-packages\Python311\site-packages\aiogram\bot\base.py", line 236, in request
    return await api.make_request(await self.get_session(), self.server, self.__token, method, data, files,
           ^^^^^^^^^^^^^^^^^^^^^^^^^^^^^^^^^^^^^^^^^^^^^^^^^^^^^^^^^^^^^^^^^^^^^^^^^^^^^^^^^^^^^^^^^^^^^^^^
  File "C:\Users\Malam\AppData\Local\Packages\PythonSoftwareFoundation.Python.3.11_qbz5n2kfra8p0\LocalCache\local-packages\Python311\site-packages\aiogram\bot\api.py", line 140, in make_request
    return check_result(method, response.content_type, response.status, await response.text())
           ^^^^^^^^^^^^^^^^^^^^^^^^^^^^^^^^^^^^^^^^^^^^^^^^^^^^^^^^^^^^^^^^^^^^^^^^^^^^^^^^^^^
  File "C:\Users\Malam\AppData\Local\Packages\PythonSoftwareFoundation.Python.3.11_qbz5n2kfra8p0\LocalCache\local-packages\Python311\site-packages\aiogram\bot\api.py", line 119, in check_result
    exceptions.ConflictError.detect(description)
  File "C:\Users\Malam\AppData\Local\Packages\PythonSoftwareFoundation.Python.3.11_qbz5n2kfra8p0\LocalCache\local-packages\Python311\site-packages\aiogram\utils\exceptions.py", line 140, in detect
    raise err(cls.text or description)
aiogram.utils.exceptions.TerminatedByOtherGetUpdates: Terminated by other getupdates request; make sure that only one bot instance is running
2024-09-24 17:37:48,879 [DEBUG] Make request: "getUpdates" with data: "{'offset': 106805196, 'timeout': 20}" and files "None" aiogram
2024-09-24 17:37:53,950 [DEBUG] Response for getUpdates: [409] "'{"ok":false,"error_code":409,"description":"Conflict: terminated by other getUpdates request; make sure that only one bot instance is running"}'" aiogram
2024-09-24 17:37:53,952 [ERROR] Cause exception while getting updates. aiogram.dispatcher.dispatcher
Traceback (most recent call last):
  File "C:\Users\Malam\AppData\Local\Packages\PythonSoftwareFoundation.Python.3.11_qbz5n2kfra8p0\LocalCache\local-packages\Python311\site-packages\aiogram\dispatcher\dispatcher.py", line 381, in start_polling
    updates = await self.bot.get_updates(
              ^^^^^^^^^^^^^^^^^^^^^^^^^^^
  File "C:\Users\Malam\AppData\Local\Packages\PythonSoftwareFoundation.Python.3.11_qbz5n2kfra8p0\LocalCache\local-packages\Python311\site-packages\aiogram\bot\bot.py", line 110, in get_updates
    result = await self.request(api.Methods.GET_UPDATES, payload)
             ^^^^^^^^^^^^^^^^^^^^^^^^^^^^^^^^^^^^^^^^^^^^^^^^^^^^
  File "C:\Users\Malam\AppData\Local\Packages\PythonSoftwareFoundation.Python.3.11_qbz5n2kfra8p0\LocalCache\local-packages\Python311\site-packages\aiogram\bot\base.py", line 236, in request
    return await api.make_request(await self.get_session(), self.server, self.__token, method, data, files,
           ^^^^^^^^^^^^^^^^^^^^^^^^^^^^^^^^^^^^^^^^^^^^^^^^^^^^^^^^^^^^^^^^^^^^^^^^^^^^^^^^^^^^^^^^^^^^^^^^
  File "C:\Users\Malam\AppData\Local\Packages\PythonSoftwareFoundation.Python.3.11_qbz5n2kfra8p0\LocalCache\local-packages\Python311\site-packages\aiogram\bot\api.py", line 140, in make_request
    return check_result(method, response.content_type, response.status, await response.text())
           ^^^^^^^^^^^^^^^^^^^^^^^^^^^^^^^^^^^^^^^^^^^^^^^^^^^^^^^^^^^^^^^^^^^^^^^^^^^^^^^^^^^
  File "C:\Users\Malam\AppData\Local\Packages\PythonSoftwareFoundation.Python.3.11_qbz5n2kfra8p0\LocalCache\local-packages\Python311\site-packages\aiogram\bot\api.py", line 119, in check_result
    exceptions.ConflictError.detect(description)
  File "C:\Users\Malam\AppData\Local\Packages\PythonSoftwareFoundation.Python.3.11_qbz5n2kfra8p0\LocalCache\local-packages\Python311\site-packages\aiogram\utils\exceptions.py", line 140, in detect
    raise err(cls.text or description)
aiogram.utils.exceptions.TerminatedByOtherGetUpdates: Terminated by other getupdates request; make sure that only one bot instance is running
2024-09-24 17:37:58,967 [DEBUG] Make request: "getUpdates" with data: "{'offset': 106805196, 'timeout': 20}" and files "None" aiogram
2024-09-24 17:38:04,046 [DEBUG] Response for getUpdates: [409] "'{"ok":false,"error_code":409,"description":"Conflict: terminated by other getUpdates request; make sure that only one bot instance is running"}'" aiogram
2024-09-24 17:38:04,047 [ERROR] Cause exception while getting updates. aiogram.dispatcher.dispatcher
Traceback (most recent call last):
  File "C:\Users\Malam\AppData\Local\Packages\PythonSoftwareFoundation.Python.3.11_qbz5n2kfra8p0\LocalCache\local-packages\Python311\site-packages\aiogram\dispatcher\dispatcher.py", line 381, in start_polling
    updates = await self.bot.get_updates(
              ^^^^^^^^^^^^^^^^^^^^^^^^^^^
  File "C:\Users\Malam\AppData\Local\Packages\PythonSoftwareFoundation.Python.3.11_qbz5n2kfra8p0\LocalCache\local-packages\Python311\site-packages\aiogram\bot\bot.py", line 110, in get_updates
    result = await self.request(api.Methods.GET_UPDATES, payload)
             ^^^^^^^^^^^^^^^^^^^^^^^^^^^^^^^^^^^^^^^^^^^^^^^^^^^^
  File "C:\Users\Malam\AppData\Local\Packages\PythonSoftwareFoundation.Python.3.11_qbz5n2kfra8p0\LocalCache\local-packages\Python311\site-packages\aiogram\bot\base.py", line 236, in request
    return await api.make_request(await self.get_session(), self.server, self.__token, method, data, files,
           ^^^^^^^^^^^^^^^^^^^^^^^^^^^^^^^^^^^^^^^^^^^^^^^^^^^^^^^^^^^^^^^^^^^^^^^^^^^^^^^^^^^^^^^^^^^^^^^^
  File "C:\Users\Malam\AppData\Local\Packages\PythonSoftwareFoundation.Python.3.11_qbz5n2kfra8p0\LocalCache\local-packages\Python311\site-packages\aiogram\bot\api.py", line 140, in make_request
    return check_result(method, response.content_type, response.status, await response.text())
           ^^^^^^^^^^^^^^^^^^^^^^^^^^^^^^^^^^^^^^^^^^^^^^^^^^^^^^^^^^^^^^^^^^^^^^^^^^^^^^^^^^^
  File "C:\Users\Malam\AppData\Local\Packages\PythonSoftwareFoundation.Python.3.11_qbz5n2kfra8p0\LocalCache\local-packages\Python311\site-packages\aiogram\bot\api.py", line 119, in check_result
    exceptions.ConflictError.detect(description)
  File "C:\Users\Malam\AppData\Local\Packages\PythonSoftwareFoundation.Python.3.11_qbz5n2kfra8p0\LocalCache\local-packages\Python311\site-packages\aiogram\utils\exceptions.py", line 140, in detect
    raise err(cls.text or description)
aiogram.utils.exceptions.TerminatedByOtherGetUpdates: Terminated by other getupdates request; make sure that only one bot instance is running
2024-09-24 17:38:09,063 [DEBUG] Make request: "getUpdates" with data: "{'offset': 106805196, 'timeout': 20}" and files "None" aiogram
2024-09-24 17:38:14,132 [DEBUG] Response for getUpdates: [409] "'{"ok":false,"error_code":409,"description":"Conflict: terminated by other getUpdates request; make sure that only one bot instance is running"}'" aiogram
2024-09-24 17:38:14,133 [ERROR] Cause exception while getting updates. aiogram.dispatcher.dispatcher
Traceback (most recent call last):
  File "C:\Users\Malam\AppData\Local\Packages\PythonSoftwareFoundation.Python.3.11_qbz5n2kfra8p0\LocalCache\local-packages\Python311\site-packages\aiogram\dispatcher\dispatcher.py", line 381, in start_polling
    updates = await self.bot.get_updates(
              ^^^^^^^^^^^^^^^^^^^^^^^^^^^
  File "C:\Users\Malam\AppData\Local\Packages\PythonSoftwareFoundation.Python.3.11_qbz5n2kfra8p0\LocalCache\local-packages\Python311\site-packages\aiogram\bot\bot.py", line 110, in get_updates
    result = await self.request(api.Methods.GET_UPDATES, payload)
             ^^^^^^^^^^^^^^^^^^^^^^^^^^^^^^^^^^^^^^^^^^^^^^^^^^^^
  File "C:\Users\Malam\AppData\Local\Packages\PythonSoftwareFoundation.Python.3.11_qbz5n2kfra8p0\LocalCache\local-packages\Python311\site-packages\aiogram\bot\base.py", line 236, in request
    return await api.make_request(await self.get_session(), self.server, self.__token, method, data, files,
           ^^^^^^^^^^^^^^^^^^^^^^^^^^^^^^^^^^^^^^^^^^^^^^^^^^^^^^^^^^^^^^^^^^^^^^^^^^^^^^^^^^^^^^^^^^^^^^^^
  File "C:\Users\Malam\AppData\Local\Packages\PythonSoftwareFoundation.Python.3.11_qbz5n2kfra8p0\LocalCache\local-packages\Python311\site-packages\aiogram\bot\api.py", line 140, in make_request
    return check_result(method, response.content_type, response.status, await response.text())
           ^^^^^^^^^^^^^^^^^^^^^^^^^^^^^^^^^^^^^^^^^^^^^^^^^^^^^^^^^^^^^^^^^^^^^^^^^^^^^^^^^^^
  File "C:\Users\Malam\AppData\Local\Packages\PythonSoftwareFoundation.Python.3.11_qbz5n2kfra8p0\LocalCache\local-packages\Python311\site-packages\aiogram\bot\api.py", line 119, in check_result
    exceptions.ConflictError.detect(description)
  File "C:\Users\Malam\AppData\Local\Packages\PythonSoftwareFoundation.Python.3.11_qbz5n2kfra8p0\LocalCache\local-packages\Python311\site-packages\aiogram\utils\exceptions.py", line 140, in detect
    raise err(cls.text or description)
aiogram.utils.exceptions.TerminatedByOtherGetUpdates: Terminated by other getupdates request; make sure that only one bot instance is running
2024-09-24 17:38:19,143 [DEBUG] Make request: "getUpdates" with data: "{'offset': 106805196, 'timeout': 20}" and files "None" aiogram
2024-09-24 17:38:24,210 [DEBUG] Response for getUpdates: [409] "'{"ok":false,"error_code":409,"description":"Conflict: terminated by other getUpdates request; make sure that only one bot instance is running"}'" aiogram
2024-09-24 17:38:24,211 [ERROR] Cause exception while getting updates. aiogram.dispatcher.dispatcher
Traceback (most recent call last):
  File "C:\Users\Malam\AppData\Local\Packages\PythonSoftwareFoundation.Python.3.11_qbz5n2kfra8p0\LocalCache\local-packages\Python311\site-packages\aiogram\dispatcher\dispatcher.py", line 381, in start_polling
    updates = await self.bot.get_updates(
              ^^^^^^^^^^^^^^^^^^^^^^^^^^^
  File "C:\Users\Malam\AppData\Local\Packages\PythonSoftwareFoundation.Python.3.11_qbz5n2kfra8p0\LocalCache\local-packages\Python311\site-packages\aiogram\bot\bot.py", line 110, in get_updates
    result = await self.request(api.Methods.GET_UPDATES, payload)
             ^^^^^^^^^^^^^^^^^^^^^^^^^^^^^^^^^^^^^^^^^^^^^^^^^^^^
  File "C:\Users\Malam\AppData\Local\Packages\PythonSoftwareFoundation.Python.3.11_qbz5n2kfra8p0\LocalCache\local-packages\Python311\site-packages\aiogram\bot\base.py", line 236, in request
    return await api.make_request(await self.get_session(), self.server, self.__token, method, data, files,
           ^^^^^^^^^^^^^^^^^^^^^^^^^^^^^^^^^^^^^^^^^^^^^^^^^^^^^^^^^^^^^^^^^^^^^^^^^^^^^^^^^^^^^^^^^^^^^^^^
  File "C:\Users\Malam\AppData\Local\Packages\PythonSoftwareFoundation.Python.3.11_qbz5n2kfra8p0\LocalCache\local-packages\Python311\site-packages\aiogram\bot\api.py", line 140, in make_request
    return check_result(method, response.content_type, response.status, await response.text())
           ^^^^^^^^^^^^^^^^^^^^^^^^^^^^^^^^^^^^^^^^^^^^^^^^^^^^^^^^^^^^^^^^^^^^^^^^^^^^^^^^^^^
  File "C:\Users\Malam\AppData\Local\Packages\PythonSoftwareFoundation.Python.3.11_qbz5n2kfra8p0\LocalCache\local-packages\Python311\site-packages\aiogram\bot\api.py", line 119, in check_result
    exceptions.ConflictError.detect(description)
  File "C:\Users\Malam\AppData\Local\Packages\PythonSoftwareFoundation.Python.3.11_qbz5n2kfra8p0\LocalCache\local-packages\Python311\site-packages\aiogram\utils\exceptions.py", line 140, in detect
    raise err(cls.text or description)
aiogram.utils.exceptions.TerminatedByOtherGetUpdates: Terminated by other getupdates request; make sure that only one bot instance is running
2024-09-24 17:38:29,228 [DEBUG] Make request: "getUpdates" with data: "{'offset': 106805196, 'timeout': 20}" and files "None" aiogram
2024-09-24 17:38:34,296 [DEBUG] Response for getUpdates: [409] "'{"ok":false,"error_code":409,"description":"Conflict: terminated by other getUpdates request; make sure that only one bot instance is running"}'" aiogram
2024-09-24 17:38:34,297 [ERROR] Cause exception while getting updates. aiogram.dispatcher.dispatcher
Traceback (most recent call last):
  File "C:\Users\Malam\AppData\Local\Packages\PythonSoftwareFoundation.Python.3.11_qbz5n2kfra8p0\LocalCache\local-packages\Python311\site-packages\aiogram\dispatcher\dispatcher.py", line 381, in start_polling
    updates = await self.bot.get_updates(
              ^^^^^^^^^^^^^^^^^^^^^^^^^^^
  File "C:\Users\Malam\AppData\Local\Packages\PythonSoftwareFoundation.Python.3.11_qbz5n2kfra8p0\LocalCache\local-packages\Python311\site-packages\aiogram\bot\bot.py", line 110, in get_updates
    result = await self.request(api.Methods.GET_UPDATES, payload)
             ^^^^^^^^^^^^^^^^^^^^^^^^^^^^^^^^^^^^^^^^^^^^^^^^^^^^
  File "C:\Users\Malam\AppData\Local\Packages\PythonSoftwareFoundation.Python.3.11_qbz5n2kfra8p0\LocalCache\local-packages\Python311\site-packages\aiogram\bot\base.py", line 236, in request
    return await api.make_request(await self.get_session(), self.server, self.__token, method, data, files,
           ^^^^^^^^^^^^^^^^^^^^^^^^^^^^^^^^^^^^^^^^^^^^^^^^^^^^^^^^^^^^^^^^^^^^^^^^^^^^^^^^^^^^^^^^^^^^^^^^
  File "C:\Users\Malam\AppData\Local\Packages\PythonSoftwareFoundation.Python.3.11_qbz5n2kfra8p0\LocalCache\local-packages\Python311\site-packages\aiogram\bot\api.py", line 140, in make_request
    return check_result(method, response.content_type, response.status, await response.text())
           ^^^^^^^^^^^^^^^^^^^^^^^^^^^^^^^^^^^^^^^^^^^^^^^^^^^^^^^^^^^^^^^^^^^^^^^^^^^^^^^^^^^
  File "C:\Users\Malam\AppData\Local\Packages\PythonSoftwareFoundation.Python.3.11_qbz5n2kfra8p0\LocalCache\local-packages\Python311\site-packages\aiogram\bot\api.py", line 119, in check_result
    exceptions.ConflictError.detect(description)
  File "C:\Users\Malam\AppData\Local\Packages\PythonSoftwareFoundation.Python.3.11_qbz5n2kfra8p0\LocalCache\local-packages\Python311\site-packages\aiogram\utils\exceptions.py", line 140, in detect
    raise err(cls.text or description)
aiogram.utils.exceptions.TerminatedByOtherGetUpdates: Terminated by other getupdates request; make sure that only one bot instance is running
2024-09-24 17:38:39,313 [DEBUG] Make request: "getUpdates" with data: "{'offset': 106805196, 'timeout': 20}" and files "None" aiogram
2024-09-24 17:38:44,404 [DEBUG] Response for getUpdates: [409] "'{"ok":false,"error_code":409,"description":"Conflict: terminated by other getUpdates request; make sure that only one bot instance is running"}'" aiogram
2024-09-24 17:38:44,404 [ERROR] Cause exception while getting updates. aiogram.dispatcher.dispatcher
Traceback (most recent call last):
  File "C:\Users\Malam\AppData\Local\Packages\PythonSoftwareFoundation.Python.3.11_qbz5n2kfra8p0\LocalCache\local-packages\Python311\site-packages\aiogram\dispatcher\dispatcher.py", line 381, in start_polling
    updates = await self.bot.get_updates(
              ^^^^^^^^^^^^^^^^^^^^^^^^^^^
  File "C:\Users\Malam\AppData\Local\Packages\PythonSoftwareFoundation.Python.3.11_qbz5n2kfra8p0\LocalCache\local-packages\Python311\site-packages\aiogram\bot\bot.py", line 110, in get_updates
    result = await self.request(api.Methods.GET_UPDATES, payload)
             ^^^^^^^^^^^^^^^^^^^^^^^^^^^^^^^^^^^^^^^^^^^^^^^^^^^^
  File "C:\Users\Malam\AppData\Local\Packages\PythonSoftwareFoundation.Python.3.11_qbz5n2kfra8p0\LocalCache\local-packages\Python311\site-packages\aiogram\bot\base.py", line 236, in request
    return await api.make_request(await self.get_session(), self.server, self.__token, method, data, files,
           ^^^^^^^^^^^^^^^^^^^^^^^^^^^^^^^^^^^^^^^^^^^^^^^^^^^^^^^^^^^^^^^^^^^^^^^^^^^^^^^^^^^^^^^^^^^^^^^^
  File "C:\Users\Malam\AppData\Local\Packages\PythonSoftwareFoundation.Python.3.11_qbz5n2kfra8p0\LocalCache\local-packages\Python311\site-packages\aiogram\bot\api.py", line 140, in make_request
    return check_result(method, response.content_type, response.status, await response.text())
           ^^^^^^^^^^^^^^^^^^^^^^^^^^^^^^^^^^^^^^^^^^^^^^^^^^^^^^^^^^^^^^^^^^^^^^^^^^^^^^^^^^^
  File "C:\Users\Malam\AppData\Local\Packages\PythonSoftwareFoundation.Python.3.11_qbz5n2kfra8p0\LocalCache\local-packages\Python311\site-packages\aiogram\bot\api.py", line 119, in check_result
    exceptions.ConflictError.detect(description)
  File "C:\Users\Malam\AppData\Local\Packages\PythonSoftwareFoundation.Python.3.11_qbz5n2kfra8p0\LocalCache\local-packages\Python311\site-packages\aiogram\utils\exceptions.py", line 140, in detect
    raise err(cls.text or description)
aiogram.utils.exceptions.TerminatedByOtherGetUpdates: Terminated by other getupdates request; make sure that only one bot instance is running
2024-09-24 17:38:49,407 [DEBUG] Make request: "getUpdates" with data: "{'offset': 106805196, 'timeout': 20}" and files "None" aiogram
2024-09-24 17:38:54,473 [DEBUG] Response for getUpdates: [409] "'{"ok":false,"error_code":409,"description":"Conflict: terminated by other getUpdates request; make sure that only one bot instance is running"}'" aiogram
2024-09-24 17:38:54,473 [ERROR] Cause exception while getting updates. aiogram.dispatcher.dispatcher
Traceback (most recent call last):
  File "C:\Users\Malam\AppData\Local\Packages\PythonSoftwareFoundation.Python.3.11_qbz5n2kfra8p0\LocalCache\local-packages\Python311\site-packages\aiogram\dispatcher\dispatcher.py", line 381, in start_polling
    updates = await self.bot.get_updates(
              ^^^^^^^^^^^^^^^^^^^^^^^^^^^
  File "C:\Users\Malam\AppData\Local\Packages\PythonSoftwareFoundation.Python.3.11_qbz5n2kfra8p0\LocalCache\local-packages\Python311\site-packages\aiogram\bot\bot.py", line 110, in get_updates
    result = await self.request(api.Methods.GET_UPDATES, payload)
             ^^^^^^^^^^^^^^^^^^^^^^^^^^^^^^^^^^^^^^^^^^^^^^^^^^^^
  File "C:\Users\Malam\AppData\Local\Packages\PythonSoftwareFoundation.Python.3.11_qbz5n2kfra8p0\LocalCache\local-packages\Python311\site-packages\aiogram\bot\base.py", line 236, in request
    return await api.make_request(await self.get_session(), self.server, self.__token, method, data, files,
           ^^^^^^^^^^^^^^^^^^^^^^^^^^^^^^^^^^^^^^^^^^^^^^^^^^^^^^^^^^^^^^^^^^^^^^^^^^^^^^^^^^^^^^^^^^^^^^^^
  File "C:\Users\Malam\AppData\Local\Packages\PythonSoftwareFoundation.Python.3.11_qbz5n2kfra8p0\LocalCache\local-packages\Python311\site-packages\aiogram\bot\api.py", line 140, in make_request
    return check_result(method, response.content_type, response.status, await response.text())
           ^^^^^^^^^^^^^^^^^^^^^^^^^^^^^^^^^^^^^^^^^^^^^^^^^^^^^^^^^^^^^^^^^^^^^^^^^^^^^^^^^^^
  File "C:\Users\Malam\AppData\Local\Packages\PythonSoftwareFoundation.Python.3.11_qbz5n2kfra8p0\LocalCache\local-packages\Python311\site-packages\aiogram\bot\api.py", line 119, in check_result
    exceptions.ConflictError.detect(description)
  File "C:\Users\Malam\AppData\Local\Packages\PythonSoftwareFoundation.Python.3.11_qbz5n2kfra8p0\LocalCache\local-packages\Python311\site-packages\aiogram\utils\exceptions.py", line 140, in detect
    raise err(cls.text or description)
aiogram.utils.exceptions.TerminatedByOtherGetUpdates: Terminated by other getupdates request; make sure that only one bot instance is running
2024-09-24 17:38:59,481 [DEBUG] Make request: "getUpdates" with data: "{'offset': 106805196, 'timeout': 20}" and files "None" aiogram
2024-09-24 17:39:04,559 [DEBUG] Response for getUpdates: [409] "'{"ok":false,"error_code":409,"description":"Conflict: terminated by other getUpdates request; make sure that only one bot instance is running"}'" aiogram
2024-09-24 17:39:04,560 [ERROR] Cause exception while getting updates. aiogram.dispatcher.dispatcher
Traceback (most recent call last):
  File "C:\Users\Malam\AppData\Local\Packages\PythonSoftwareFoundation.Python.3.11_qbz5n2kfra8p0\LocalCache\local-packages\Python311\site-packages\aiogram\dispatcher\dispatcher.py", line 381, in start_polling
    updates = await self.bot.get_updates(
              ^^^^^^^^^^^^^^^^^^^^^^^^^^^
  File "C:\Users\Malam\AppData\Local\Packages\PythonSoftwareFoundation.Python.3.11_qbz5n2kfra8p0\LocalCache\local-packages\Python311\site-packages\aiogram\bot\bot.py", line 110, in get_updates
    result = await self.request(api.Methods.GET_UPDATES, payload)
             ^^^^^^^^^^^^^^^^^^^^^^^^^^^^^^^^^^^^^^^^^^^^^^^^^^^^
  File "C:\Users\Malam\AppData\Local\Packages\PythonSoftwareFoundation.Python.3.11_qbz5n2kfra8p0\LocalCache\local-packages\Python311\site-packages\aiogram\bot\base.py", line 236, in request
    return await api.make_request(await self.get_session(), self.server, self.__token, method, data, files,
           ^^^^^^^^^^^^^^^^^^^^^^^^^^^^^^^^^^^^^^^^^^^^^^^^^^^^^^^^^^^^^^^^^^^^^^^^^^^^^^^^^^^^^^^^^^^^^^^^
  File "C:\Users\Malam\AppData\Local\Packages\PythonSoftwareFoundation.Python.3.11_qbz5n2kfra8p0\LocalCache\local-packages\Python311\site-packages\aiogram\bot\api.py", line 140, in make_request
    return check_result(method, response.content_type, response.status, await response.text())
           ^^^^^^^^^^^^^^^^^^^^^^^^^^^^^^^^^^^^^^^^^^^^^^^^^^^^^^^^^^^^^^^^^^^^^^^^^^^^^^^^^^^
  File "C:\Users\Malam\AppData\Local\Packages\PythonSoftwareFoundation.Python.3.11_qbz5n2kfra8p0\LocalCache\local-packages\Python311\site-packages\aiogram\bot\api.py", line 119, in check_result
    exceptions.ConflictError.detect(description)
  File "C:\Users\Malam\AppData\Local\Packages\PythonSoftwareFoundation.Python.3.11_qbz5n2kfra8p0\LocalCache\local-packages\Python311\site-packages\aiogram\utils\exceptions.py", line 140, in detect
    raise err(cls.text or description)
aiogram.utils.exceptions.TerminatedByOtherGetUpdates: Terminated by other getupdates request; make sure that only one bot instance is running
2024-09-24 17:39:09,566 [DEBUG] Make request: "getUpdates" with data: "{'offset': 106805196, 'timeout': 20}" and files "None" aiogram
2024-09-24 17:39:14,683 [DEBUG] Response for getUpdates: [409] "'{"ok":false,"error_code":409,"description":"Conflict: terminated by other getUpdates request; make sure that only one bot instance is running"}'" aiogram
2024-09-24 17:39:14,683 [ERROR] Cause exception while getting updates. aiogram.dispatcher.dispatcher
Traceback (most recent call last):
  File "C:\Users\Malam\AppData\Local\Packages\PythonSoftwareFoundation.Python.3.11_qbz5n2kfra8p0\LocalCache\local-packages\Python311\site-packages\aiogram\dispatcher\dispatcher.py", line 381, in start_polling
    updates = await self.bot.get_updates(
              ^^^^^^^^^^^^^^^^^^^^^^^^^^^
  File "C:\Users\Malam\AppData\Local\Packages\PythonSoftwareFoundation.Python.3.11_qbz5n2kfra8p0\LocalCache\local-packages\Python311\site-packages\aiogram\bot\bot.py", line 110, in get_updates
    result = await self.request(api.Methods.GET_UPDATES, payload)
             ^^^^^^^^^^^^^^^^^^^^^^^^^^^^^^^^^^^^^^^^^^^^^^^^^^^^
  File "C:\Users\Malam\AppData\Local\Packages\PythonSoftwareFoundation.Python.3.11_qbz5n2kfra8p0\LocalCache\local-packages\Python311\site-packages\aiogram\bot\base.py", line 236, in request
    return await api.make_request(await self.get_session(), self.server, self.__token, method, data, files,
           ^^^^^^^^^^^^^^^^^^^^^^^^^^^^^^^^^^^^^^^^^^^^^^^^^^^^^^^^^^^^^^^^^^^^^^^^^^^^^^^^^^^^^^^^^^^^^^^^
  File "C:\Users\Malam\AppData\Local\Packages\PythonSoftwareFoundation.Python.3.11_qbz5n2kfra8p0\LocalCache\local-packages\Python311\site-packages\aiogram\bot\api.py", line 140, in make_request
    return check_result(method, response.content_type, response.status, await response.text())
           ^^^^^^^^^^^^^^^^^^^^^^^^^^^^^^^^^^^^^^^^^^^^^^^^^^^^^^^^^^^^^^^^^^^^^^^^^^^^^^^^^^^
  File "C:\Users\Malam\AppData\Local\Packages\PythonSoftwareFoundation.Python.3.11_qbz5n2kfra8p0\LocalCache\local-packages\Python311\site-packages\aiogram\bot\api.py", line 119, in check_result
    exceptions.ConflictError.detect(description)
  File "C:\Users\Malam\AppData\Local\Packages\PythonSoftwareFoundation.Python.3.11_qbz5n2kfra8p0\LocalCache\local-packages\Python311\site-packages\aiogram\utils\exceptions.py", line 140, in detect
    raise err(cls.text or description)
aiogram.utils.exceptions.TerminatedByOtherGetUpdates: Terminated by other getupdates request; make sure that only one bot instance is running
2024-09-24 17:39:19,697 [DEBUG] Make request: "getUpdates" with data: "{'offset': 106805196, 'timeout': 20}" and files "None" aiogram
2024-09-24 17:39:24,813 [DEBUG] Response for getUpdates: [409] "'{"ok":false,"error_code":409,"description":"Conflict: terminated by other getUpdates request; make sure that only one bot instance is running"}'" aiogram
2024-09-24 17:39:24,814 [ERROR] Cause exception while getting updates. aiogram.dispatcher.dispatcher
Traceback (most recent call last):
  File "C:\Users\Malam\AppData\Local\Packages\PythonSoftwareFoundation.Python.3.11_qbz5n2kfra8p0\LocalCache\local-packages\Python311\site-packages\aiogram\dispatcher\dispatcher.py", line 381, in start_polling
    updates = await self.bot.get_updates(
              ^^^^^^^^^^^^^^^^^^^^^^^^^^^
  File "C:\Users\Malam\AppData\Local\Packages\PythonSoftwareFoundation.Python.3.11_qbz5n2kfra8p0\LocalCache\local-packages\Python311\site-packages\aiogram\bot\bot.py", line 110, in get_updates
    result = await self.request(api.Methods.GET_UPDATES, payload)
             ^^^^^^^^^^^^^^^^^^^^^^^^^^^^^^^^^^^^^^^^^^^^^^^^^^^^
  File "C:\Users\Malam\AppData\Local\Packages\PythonSoftwareFoundation.Python.3.11_qbz5n2kfra8p0\LocalCache\local-packages\Python311\site-packages\aiogram\bot\base.py", line 236, in request
    return await api.make_request(await self.get_session(), self.server, self.__token, method, data, files,
           ^^^^^^^^^^^^^^^^^^^^^^^^^^^^^^^^^^^^^^^^^^^^^^^^^^^^^^^^^^^^^^^^^^^^^^^^^^^^^^^^^^^^^^^^^^^^^^^^
  File "C:\Users\Malam\AppData\Local\Packages\PythonSoftwareFoundation.Python.3.11_qbz5n2kfra8p0\LocalCache\local-packages\Python311\site-packages\aiogram\bot\api.py", line 140, in make_request
    return check_result(method, response.content_type, response.status, await response.text())
           ^^^^^^^^^^^^^^^^^^^^^^^^^^^^^^^^^^^^^^^^^^^^^^^^^^^^^^^^^^^^^^^^^^^^^^^^^^^^^^^^^^^
  File "C:\Users\Malam\AppData\Local\Packages\PythonSoftwareFoundation.Python.3.11_qbz5n2kfra8p0\LocalCache\local-packages\Python311\site-packages\aiogram\bot\api.py", line 119, in check_result
    exceptions.ConflictError.detect(description)
  File "C:\Users\Malam\AppData\Local\Packages\PythonSoftwareFoundation.Python.3.11_qbz5n2kfra8p0\LocalCache\local-packages\Python311\site-packages\aiogram\utils\exceptions.py", line 140, in detect
    raise err(cls.text or description)
aiogram.utils.exceptions.TerminatedByOtherGetUpdates: Terminated by other getupdates request; make sure that only one bot instance is running
2024-09-24 17:39:29,831 [DEBUG] Make request: "getUpdates" with data: "{'offset': 106805196, 'timeout': 20}" and files "None" aiogram
2024-09-24 17:39:34,902 [DEBUG] Response for getUpdates: [409] "'{"ok":false,"error_code":409,"description":"Conflict: terminated by other getUpdates request; make sure that only one bot instance is running"}'" aiogram
2024-09-24 17:39:34,903 [ERROR] Cause exception while getting updates. aiogram.dispatcher.dispatcher
Traceback (most recent call last):
  File "C:\Users\Malam\AppData\Local\Packages\PythonSoftwareFoundation.Python.3.11_qbz5n2kfra8p0\LocalCache\local-packages\Python311\site-packages\aiogram\dispatcher\dispatcher.py", line 381, in start_polling
    updates = await self.bot.get_updates(
              ^^^^^^^^^^^^^^^^^^^^^^^^^^^
  File "C:\Users\Malam\AppData\Local\Packages\PythonSoftwareFoundation.Python.3.11_qbz5n2kfra8p0\LocalCache\local-packages\Python311\site-packages\aiogram\bot\bot.py", line 110, in get_updates
    result = await self.request(api.Methods.GET_UPDATES, payload)
             ^^^^^^^^^^^^^^^^^^^^^^^^^^^^^^^^^^^^^^^^^^^^^^^^^^^^
  File "C:\Users\Malam\AppData\Local\Packages\PythonSoftwareFoundation.Python.3.11_qbz5n2kfra8p0\LocalCache\local-packages\Python311\site-packages\aiogram\bot\base.py", line 236, in request
    return await api.make_request(await self.get_session(), self.server, self.__token, method, data, files,
           ^^^^^^^^^^^^^^^^^^^^^^^^^^^^^^^^^^^^^^^^^^^^^^^^^^^^^^^^^^^^^^^^^^^^^^^^^^^^^^^^^^^^^^^^^^^^^^^^
  File "C:\Users\Malam\AppData\Local\Packages\PythonSoftwareFoundation.Python.3.11_qbz5n2kfra8p0\LocalCache\local-packages\Python311\site-packages\aiogram\bot\api.py", line 140, in make_request
    return check_result(method, response.content_type, response.status, await response.text())
           ^^^^^^^^^^^^^^^^^^^^^^^^^^^^^^^^^^^^^^^^^^^^^^^^^^^^^^^^^^^^^^^^^^^^^^^^^^^^^^^^^^^
  File "C:\Users\Malam\AppData\Local\Packages\PythonSoftwareFoundation.Python.3.11_qbz5n2kfra8p0\LocalCache\local-packages\Python311\site-packages\aiogram\bot\api.py", line 119, in check_result
    exceptions.ConflictError.detect(description)
  File "C:\Users\Malam\AppData\Local\Packages\PythonSoftwareFoundation.Python.3.11_qbz5n2kfra8p0\LocalCache\local-packages\Python311\site-packages\aiogram\utils\exceptions.py", line 140, in detect
    raise err(cls.text or description)
aiogram.utils.exceptions.TerminatedByOtherGetUpdates: Terminated by other getupdates request; make sure that only one bot instance is running
2024-09-24 17:39:39,914 [DEBUG] Make request: "getUpdates" with data: "{'offset': 106805196, 'timeout': 20}" and files "None" aiogram
2024-09-24 17:39:45,056 [DEBUG] Response for getUpdates: [409] "'{"ok":false,"error_code":409,"description":"Conflict: terminated by other getUpdates request; make sure that only one bot instance is running"}'" aiogram
2024-09-24 17:39:45,056 [ERROR] Cause exception while getting updates. aiogram.dispatcher.dispatcher
Traceback (most recent call last):
  File "C:\Users\Malam\AppData\Local\Packages\PythonSoftwareFoundation.Python.3.11_qbz5n2kfra8p0\LocalCache\local-packages\Python311\site-packages\aiogram\dispatcher\dispatcher.py", line 381, in start_polling
    updates = await self.bot.get_updates(
              ^^^^^^^^^^^^^^^^^^^^^^^^^^^
  File "C:\Users\Malam\AppData\Local\Packages\PythonSoftwareFoundation.Python.3.11_qbz5n2kfra8p0\LocalCache\local-packages\Python311\site-packages\aiogram\bot\bot.py", line 110, in get_updates
    result = await self.request(api.Methods.GET_UPDATES, payload)
             ^^^^^^^^^^^^^^^^^^^^^^^^^^^^^^^^^^^^^^^^^^^^^^^^^^^^
  File "C:\Users\Malam\AppData\Local\Packages\PythonSoftwareFoundation.Python.3.11_qbz5n2kfra8p0\LocalCache\local-packages\Python311\site-packages\aiogram\bot\base.py", line 236, in request
    return await api.make_request(await self.get_session(), self.server, self.__token, method, data, files,
           ^^^^^^^^^^^^^^^^^^^^^^^^^^^^^^^^^^^^^^^^^^^^^^^^^^^^^^^^^^^^^^^^^^^^^^^^^^^^^^^^^^^^^^^^^^^^^^^^
  File "C:\Users\Malam\AppData\Local\Packages\PythonSoftwareFoundation.Python.3.11_qbz5n2kfra8p0\LocalCache\local-packages\Python311\site-packages\aiogram\bot\api.py", line 140, in make_request
    return check_result(method, response.content_type, response.status, await response.text())
           ^^^^^^^^^^^^^^^^^^^^^^^^^^^^^^^^^^^^^^^^^^^^^^^^^^^^^^^^^^^^^^^^^^^^^^^^^^^^^^^^^^^
  File "C:\Users\Malam\AppData\Local\Packages\PythonSoftwareFoundation.Python.3.11_qbz5n2kfra8p0\LocalCache\local-packages\Python311\site-packages\aiogram\bot\api.py", line 119, in check_result
    exceptions.ConflictError.detect(description)
  File "C:\Users\Malam\AppData\Local\Packages\PythonSoftwareFoundation.Python.3.11_qbz5n2kfra8p0\LocalCache\local-packages\Python311\site-packages\aiogram\utils\exceptions.py", line 140, in detect
    raise err(cls.text or description)
aiogram.utils.exceptions.TerminatedByOtherGetUpdates: Terminated by other getupdates request; make sure that only one bot instance is running
2024-09-24 17:39:50,066 [DEBUG] Make request: "getUpdates" with data: "{'offset': 106805196, 'timeout': 20}" and files "None" aiogram
2024-09-24 17:39:53,574 [WARNING] Polling is stopped. aiogram.dispatcher.dispatcher
2024-09-24 17:39:53,597 [INFO] Stop polling... aiogram.dispatcher.dispatcher
2024-09-24 17:39:53,598 [ERROR] Unclosed client session
client_session: <aiohttp.client.ClientSession object at 0x000002767E18EED0> asyncio
2024-09-24 17:39:56,300 [DEBUG] Loaded middleware 'LoggingMiddleware' aiogram.Middleware
2024-09-24 17:39:56,302 [DEBUG] Using proactor: IocpProactor asyncio
2024-09-24 17:39:56,304 [INFO] Инициализация базы данных начата........................................................................................................................................ root
2024-09-24 17:39:56,304 [DEBUG] executing <function connect.<locals>.connector at 0x000001DF5C59C220> aiosqlite
2024-09-24 17:39:56,305 [DEBUG] operation <function connect.<locals>.connector at 0x000001DF5C59C220> completed aiosqlite
2024-09-24 17:39:56,306 [DEBUG] executing functools.partial(<built-in method execute of sqlite3.Connection object at 0x000001DF5C53A6B0>, 'PRAGMA journal_mode=WAL;', []) aiosqlite
2024-09-24 17:39:56,307 [DEBUG] operation functools.partial(<built-in method execute of sqlite3.Connection object at 0x000001DF5C53A6B0>, 'PRAGMA journal_mode=WAL;', []) completed aiosqlite
2024-09-24 17:39:56,308 [INFO] Таблица users создается root
2024-09-24 17:39:56,308 [DEBUG] executing functools.partial(<built-in method execute of sqlite3.Connection object at 0x000001DF5C53A6B0>, '\n                CREATE TABLE IF NOT EXISTS users (\n                    user_id INTEGER PRIMARY KEY,\n                    username TEXT NOT NULL,\n                    balance REAL DEFAULT 0\n                )\n            ', []) aiosqlite
2024-09-24 17:39:56,309 [DEBUG] operation functools.partial(<built-in method execute of sqlite3.Connection object at 0x000001DF5C53A6B0>, '\n                CREATE TABLE IF NOT EXISTS users (\n                    user_id INTEGER PRIMARY KEY,\n                    username TEXT NOT NULL,\n                    balance REAL DEFAULT 0\n                )\n            ', []) completed aiosqlite
2024-09-24 17:39:56,309 [INFO] Таблица users успешно создана или уже существует. root
2024-09-24 17:39:56,309 [INFO] Таблица cars создается root
2024-09-24 17:39:56,309 [DEBUG] executing functools.partial(<built-in method execute of sqlite3.Connection object at 0x000001DF5C53A6B0>, '\n                CREATE TABLE IF NOT EXISTS cars (\n                    car_id INTEGER PRIMARY KEY,\n                    name TEXT NOT NULL,\n                    price REAL NOT NULL,\n                    power REAL NOT NULL,\n                    type TEXT NOT NULL\n                )\n            ', []) aiosqlite
2024-09-24 17:39:56,310 [DEBUG] operation functools.partial(<built-in method execute of sqlite3.Connection object at 0x000001DF5C53A6B0>, '\n                CREATE TABLE IF NOT EXISTS cars (\n                    car_id INTEGER PRIMARY KEY,\n                    name TEXT NOT NULL,\n                    price REAL NOT NULL,\n                    power REAL NOT NULL,\n                    type TEXT NOT NULL\n                )\n            ', []) completed aiosqlite
2024-09-24 17:39:56,310 [INFO] Таблица cars успешно создана или уже существует. root
2024-09-24 17:39:56,310 [INFO] Таблица purchases создается root
2024-09-24 17:39:56,311 [DEBUG] executing functools.partial(<built-in method execute of sqlite3.Connection object at 0x000001DF5C53A6B0>, '\n                CREATE TABLE IF NOT EXISTS purchases (\n                    user_id INTEGER,\n                    car_id INTEGER,\n                    purchase_date TEXT NOT NULL,\n                    FOREIGN KEY(user_id) REFERENCES users(user_id) ON DELETE CASCADE,\n                    FOREIGN KEY(car_id) REFERENCES cars(car_id) ON DELETE CASCADE\n                )\n            ', []) aiosqlite
2024-09-24 17:39:56,311 [DEBUG] operation functools.partial(<built-in method execute of sqlite3.Connection object at 0x000001DF5C53A6B0>, '\n                CREATE TABLE IF NOT EXISTS purchases (\n                    user_id INTEGER,\n                    car_id INTEGER,\n                    purchase_date TEXT NOT NULL,\n                    FOREIGN KEY(user_id) REFERENCES users(user_id) ON DELETE CASCADE,\n                    FOREIGN KEY(car_id) REFERENCES cars(car_id) ON DELETE CASCADE\n                )\n            ', []) completed aiosqlite
2024-09-24 17:39:56,312 [INFO] Таблица purchases успешно создана или уже существует. root
2024-09-24 17:39:56,312 [INFO] Таблица earnings создается root
2024-09-24 17:39:56,312 [DEBUG] executing functools.partial(<built-in method execute of sqlite3.Connection object at 0x000001DF5C53A6B0>, '\n                CREATE TABLE IF NOT EXISTS earnings (\n                    id INTEGER PRIMARY KEY AUTOINCREMENT,\n                    user_id INTEGER,\n                    amount REAL NOT NULL,\n                    timestamp TEXT NOT NULL,\n                    FOREIGN KEY(user_id) REFERENCES users(user_id) ON DELETE CASCADE\n                )\n            ', []) aiosqlite
2024-09-24 17:39:56,313 [DEBUG] operation functools.partial(<built-in method execute of sqlite3.Connection object at 0x000001DF5C53A6B0>, '\n                CREATE TABLE IF NOT EXISTS earnings (\n                    id INTEGER PRIMARY KEY AUTOINCREMENT,\n                    user_id INTEGER,\n                    amount REAL NOT NULL,\n                    timestamp TEXT NOT NULL,\n                    FOREIGN KEY(user_id) REFERENCES users(user_id) ON DELETE CASCADE\n                )\n            ', []) completed aiosqlite
2024-09-24 17:39:56,313 [INFO] Таблица earnings успешно создана или уже существует. root
2024-09-24 17:39:56,314 [INFO] Таблица channels создается root
2024-09-24 17:39:56,314 [DEBUG] executing functools.partial(<built-in method execute of sqlite3.Connection object at 0x000001DF5C53A6B0>, '\n                CREATE TABLE IF NOT EXISTS channels (\n                    id INTEGER PRIMARY KEY AUTOINCREMENT,\n                    name TEXT NOT NULL,\n                    link TEXT NOT NULL,\n                    promo_type TEXT NOT NULL\n                )\n            ', []) aiosqlite
2024-09-24 17:39:56,314 [DEBUG] operation functools.partial(<built-in method execute of sqlite3.Connection object at 0x000001DF5C53A6B0>, '\n                CREATE TABLE IF NOT EXISTS channels (\n                    id INTEGER PRIMARY KEY AUTOINCREMENT,\n                    name TEXT NOT NULL,\n                    link TEXT NOT NULL,\n                    promo_type TEXT NOT NULL\n                )\n            ', []) completed aiosqlite
2024-09-24 17:39:56,315 [INFO] Таблица channels успешно создана или уже существует. root
2024-09-24 17:39:56,315 [INFO] Добавление данных в таблицу channels root
2024-09-24 17:39:56,315 [DEBUG] executing functools.partial(<built-in method execute of sqlite3.Connection object at 0x000001DF5C53A6B0>, "\n                INSERT OR IGNORE INTO channels (name, link, promo_type) VALUES\n                ('Channel 1', 'https://t.me/channel1', 'regular'),\n                ('Channel 2', 'https://t.me/channel2', 'special'),\n                ('Channel 3', 'https://t.me/klev_ton', 'advanced')\n            ", []) aiosqlite
2024-09-24 17:39:56,316 [DEBUG] operation functools.partial(<built-in method execute of sqlite3.Connection object at 0x000001DF5C53A6B0>, "\n                INSERT OR IGNORE INTO channels (name, link, promo_type) VALUES\n                ('Channel 1', 'https://t.me/channel1', 'regular'),\n                ('Channel 2', 'https://t.me/channel2', 'special'),\n                ('Channel 3', 'https://t.me/klev_ton', 'advanced')\n            ", []) completed aiosqlite
2024-09-24 17:39:56,316 [INFO] Данные в таблицу channels успешно добавлены. root
2024-09-24 17:39:56,317 [INFO] Таблица promo_codes создается root
2024-09-24 17:39:56,317 [DEBUG] executing functools.partial(<built-in method execute of sqlite3.Connection object at 0x000001DF5C53A6B0>, '\n                CREATE TABLE IF NOT EXISTS promo_codes (\n                    id INTEGER PRIMARY KEY AUTOINCREMENT,\n                    code TEXT NOT NULL UNIQUE,\n                    category TEXT NOT NULL,\n                    reward INTEGER NOT NULL,\n                    expiration_time TEXT NOT NULL\n                )\n            ', []) aiosqlite
2024-09-24 17:39:56,317 [DEBUG] operation functools.partial(<built-in method execute of sqlite3.Connection object at 0x000001DF5C53A6B0>, '\n                CREATE TABLE IF NOT EXISTS promo_codes (\n                    id INTEGER PRIMARY KEY AUTOINCREMENT,\n                    code TEXT NOT NULL UNIQUE,\n                    category TEXT NOT NULL,\n                    reward INTEGER NOT NULL,\n                    expiration_time TEXT NOT NULL\n                )\n            ', []) completed aiosqlite
2024-09-24 17:39:56,318 [INFO] Таблица promo_codes успешно создана или уже существует. root
2024-09-24 17:39:56,318 [DEBUG] executing functools.partial(<built-in method commit of sqlite3.Connection object at 0x000001DF5C53A6B0>) aiosqlite
2024-09-24 17:39:56,323 [DEBUG] operation functools.partial(<built-in method commit of sqlite3.Connection object at 0x000001DF5C53A6B0>) completed aiosqlite
2024-09-24 17:39:56,324 [DEBUG] executing functools.partial(<built-in method close of sqlite3.Connection object at 0x000001DF5C53A6B0>) aiosqlite
2024-09-24 17:39:56,326 [DEBUG] operation functools.partial(<built-in method close of sqlite3.Connection object at 0x000001DF5C53A6B0>) completed aiosqlite
2024-09-24 17:39:56,326 [INFO] Инициализация базы данных завершена. root
2024-09-24 17:39:56,328 [DEBUG] executing <function connect.<locals>.connector at 0x000001DF5C59C220> aiosqlite
2024-09-24 17:39:56,330 [DEBUG] operation <function connect.<locals>.connector at 0x000001DF5C59C220> completed aiosqlite
2024-09-24 17:39:56,331 [DEBUG] executing functools.partial(<built-in method cursor of sqlite3.Connection object at 0x000001DF5C53A6B0>) aiosqlite
2024-09-24 17:39:56,332 [DEBUG] operation functools.partial(<built-in method cursor of sqlite3.Connection object at 0x000001DF5C53A6B0>) completed aiosqlite
2024-09-24 17:39:56,333 [DEBUG] executing functools.partial(<built-in method execute of sqlite3.Cursor object at 0x000001DF5C53FCC0>, "SELECT name FROM sqlite_master WHERE type='table';", []) aiosqlite
2024-09-24 17:39:56,336 [DEBUG] operation functools.partial(<built-in method execute of sqlite3.Cursor object at 0x000001DF5C53FCC0>, "SELECT name FROM sqlite_master WHERE type='table';", []) completed aiosqlite
2024-09-24 17:39:56,338 [DEBUG] executing functools.partial(<built-in method fetchall of sqlite3.Cursor object at 0x000001DF5C53FCC0>) aiosqlite
2024-09-24 17:39:56,338 [DEBUG] operation functools.partial(<built-in method fetchall of sqlite3.Cursor object at 0x000001DF5C53FCC0>) completed aiosqlite
2024-09-24 17:39:56,340 [INFO] Таблицы в базе данных: [('users',), ('cars',), ('purchases',), ('earnings',), ('sqlite_sequence',), ('channels',), ('promo_codes',)] root
2024-09-24 17:39:56,340 [DEBUG] executing functools.partial(<built-in method close of sqlite3.Cursor object at 0x000001DF5C53FCC0>) aiosqlite
2024-09-24 17:39:56,341 [DEBUG] operation functools.partial(<built-in method close of sqlite3.Cursor object at 0x000001DF5C53FCC0>) completed aiosqlite
2024-09-24 17:39:56,343 [DEBUG] executing functools.partial(<built-in method close of sqlite3.Connection object at 0x000001DF5C53A6B0>) aiosqlite
2024-09-24 17:39:56,344 [DEBUG] operation functools.partial(<built-in method close of sqlite3.Connection object at 0x000001DF5C53A6B0>) completed aiosqlite
2024-09-24 17:39:56,346 [DEBUG] executing <function connect.<locals>.connector at 0x000001DF5C59C4A0> aiosqlite
2024-09-24 17:39:56,348 [DEBUG] operation <function connect.<locals>.connector at 0x000001DF5C59C4A0> completed aiosqlite
2024-09-24 17:39:56,349 [INFO] Вставка заранее подготовленных промокодов в базу данных.......................................................................................................... root
2024-09-24 17:39:56,349 [DEBUG] executing functools.partial(<built-in method execute of sqlite3.Connection object at 0x000001DF5C53A6B0>, 'DELETE FROM promo_codes', []) aiosqlite
2024-09-24 17:39:56,353 [DEBUG] operation functools.partial(<built-in method execute of sqlite3.Connection object at 0x000001DF5C53A6B0>, 'DELETE FROM promo_codes', []) completed aiosqlite
2024-09-24 17:39:56,355 [INFO] Добавляем промокод: CODE1, категория: normal, награда: 10 root
2024-09-24 17:39:56,356 [DEBUG] executing functools.partial(<built-in method execute of sqlite3.Connection object at 0x000001DF5C53A6B0>, 'INSERT INTO promo_codes (code, category, reward, expiration_time) VALUES (?, ?, ?, ?)', ('CODE1', 'normal', 10, '2024-10-01 17:39:56')) aiosqlite
2024-09-24 17:39:56,356 [DEBUG] operation functools.partial(<built-in method execute of sqlite3.Connection object at 0x000001DF5C53A6B0>, 'INSERT INTO promo_codes (code, category, reward, expiration_time) VALUES (?, ?, ?, ?)', ('CODE1', 'normal', 10, '2024-10-01 17:39:56')) completed aiosqlite
2024-09-24 17:39:56,356 [INFO] Добавляем промокод: CODE2, категория: normal, награда: 10 root
2024-09-24 17:39:56,356 [DEBUG] executing functools.partial(<built-in method execute of sqlite3.Connection object at 0x000001DF5C53A6B0>, 'INSERT INTO promo_codes (code, category, reward, expiration_time) VALUES (?, ?, ?, ?)', ('CODE2', 'normal', 10, '2024-10-01 17:39:56')) aiosqlite
2024-09-24 17:39:56,357 [DEBUG] operation functools.partial(<built-in method execute of sqlite3.Connection object at 0x000001DF5C53A6B0>, 'INSERT INTO promo_codes (code, category, reward, expiration_time) VALUES (?, ?, ?, ?)', ('CODE2', 'normal', 10, '2024-10-01 17:39:56')) completed aiosqlite
2024-09-24 17:39:56,357 [INFO] Добавляем промокод: CODE3, категория: normal, награда: 10 root
2024-09-24 17:39:56,358 [DEBUG] executing functools.partial(<built-in method execute of sqlite3.Connection object at 0x000001DF5C53A6B0>, 'INSERT INTO promo_codes (code, category, reward, expiration_time) VALUES (?, ?, ?, ?)', ('CODE3', 'normal', 10, '2024-10-01 17:39:56')) aiosqlite
2024-09-24 17:39:56,358 [DEBUG] operation functools.partial(<built-in method execute of sqlite3.Connection object at 0x000001DF5C53A6B0>, 'INSERT INTO promo_codes (code, category, reward, expiration_time) VALUES (?, ?, ?, ?)', ('CODE3', 'normal', 10, '2024-10-01 17:39:56')) completed aiosqlite
2024-09-24 17:39:56,359 [INFO] Добавляем промокод: CODE4, категория: normal, награда: 30 root
2024-09-24 17:39:56,359 [DEBUG] executing functools.partial(<built-in method execute of sqlite3.Connection object at 0x000001DF5C53A6B0>, 'INSERT INTO promo_codes (code, category, reward, expiration_time) VALUES (?, ?, ?, ?)', ('CODE4', 'normal', 30, '2024-10-01 17:39:56')) aiosqlite
2024-09-24 17:39:56,359 [DEBUG] operation functools.partial(<built-in method execute of sqlite3.Connection object at 0x000001DF5C53A6B0>, 'INSERT INTO promo_codes (code, category, reward, expiration_time) VALUES (?, ?, ?, ?)', ('CODE4', 'normal', 30, '2024-10-01 17:39:56')) completed aiosqlite
2024-09-24 17:39:56,361 [INFO] Добавляем промокод: CODE5, категория: normal, награда: 30 root
2024-09-24 17:39:56,361 [DEBUG] executing functools.partial(<built-in method execute of sqlite3.Connection object at 0x000001DF5C53A6B0>, 'INSERT INTO promo_codes (code, category, reward, expiration_time) VALUES (?, ?, ?, ?)', ('CODE5', 'normal', 30, '2024-10-01 17:39:56')) aiosqlite
2024-09-24 17:39:56,361 [DEBUG] operation functools.partial(<built-in method execute of sqlite3.Connection object at 0x000001DF5C53A6B0>, 'INSERT INTO promo_codes (code, category, reward, expiration_time) VALUES (?, ?, ?, ?)', ('CODE5', 'normal', 30, '2024-10-01 17:39:56')) completed aiosqlite
2024-09-24 17:39:56,362 [INFO] Добавляем промокод: CODE6, категория: normal, награда: 50 root
2024-09-24 17:39:56,362 [DEBUG] executing functools.partial(<built-in method execute of sqlite3.Connection object at 0x000001DF5C53A6B0>, 'INSERT INTO promo_codes (code, category, reward, expiration_time) VALUES (?, ?, ?, ?)', ('CODE6', 'normal', 50, '2024-10-01 17:39:56')) aiosqlite
2024-09-24 17:39:56,362 [DEBUG] operation functools.partial(<built-in method execute of sqlite3.Connection object at 0x000001DF5C53A6B0>, 'INSERT INTO promo_codes (code, category, reward, expiration_time) VALUES (?, ?, ?, ?)', ('CODE6', 'normal', 50, '2024-10-01 17:39:56')) completed aiosqlite
2024-09-24 17:39:56,363 [INFO] Добавляем промокод: SPECIAL1, категория: special, награда: 100 root
2024-09-24 17:39:56,363 [DEBUG] executing functools.partial(<built-in method execute of sqlite3.Connection object at 0x000001DF5C53A6B0>, 'INSERT INTO promo_codes (code, category, reward, expiration_time) VALUES (?, ?, ?, ?)', ('SPECIAL1', 'special', 100, '2024-10-01 17:39:56')) aiosqlite
2024-09-24 17:39:56,363 [DEBUG] operation functools.partial(<built-in method execute of sqlite3.Connection object at 0x000001DF5C53A6B0>, 'INSERT INTO promo_codes (code, category, reward, expiration_time) VALUES (?, ?, ?, ?)', ('SPECIAL1', 'special', 100, '2024-10-01 17:39:56')) completed aiosqlite
2024-09-24 17:39:56,364 [INFO] Добавляем промокод: SPECIAL2, категория: special, награда: 150 root
2024-09-24 17:39:56,364 [DEBUG] executing functools.partial(<built-in method execute of sqlite3.Connection object at 0x000001DF5C53A6B0>, 'INSERT INTO promo_codes (code, category, reward, expiration_time) VALUES (?, ?, ?, ?)', ('SPECIAL2', 'special', 150, '2024-10-01 17:39:56')) aiosqlite
2024-09-24 17:39:56,365 [DEBUG] operation functools.partial(<built-in method execute of sqlite3.Connection object at 0x000001DF5C53A6B0>, 'INSERT INTO promo_codes (code, category, reward, expiration_time) VALUES (?, ?, ?, ?)', ('SPECIAL2', 'special', 150, '2024-10-01 17:39:56')) completed aiosqlite
2024-09-24 17:39:56,366 [INFO] Добавляем промокод: SPECIAL3, категория: special, награда: 200 root
2024-09-24 17:39:56,366 [DEBUG] executing functools.partial(<built-in method execute of sqlite3.Connection object at 0x000001DF5C53A6B0>, 'INSERT INTO promo_codes (code, category, reward, expiration_time) VALUES (?, ?, ?, ?)', ('SPECIAL3', 'special', 200, '2024-10-01 17:39:56')) aiosqlite
2024-09-24 17:39:56,366 [DEBUG] operation functools.partial(<built-in method execute of sqlite3.Connection object at 0x000001DF5C53A6B0>, 'INSERT INTO promo_codes (code, category, reward, expiration_time) VALUES (?, ?, ?, ?)', ('SPECIAL3', 'special', 200, '2024-10-01 17:39:56')) completed aiosqlite
2024-09-24 17:39:56,367 [INFO] Добавляем промокод: ADVANCED1, категория: advanced, награда: 350 root
2024-09-24 17:39:56,367 [DEBUG] executing functools.partial(<built-in method execute of sqlite3.Connection object at 0x000001DF5C53A6B0>, 'INSERT INTO promo_codes (code, category, reward, expiration_time) VALUES (?, ?, ?, ?)', ('ADVANCED1', 'advanced', 350, '2024-10-01 17:39:56')) aiosqlite
2024-09-24 17:39:56,367 [DEBUG] operation functools.partial(<built-in method execute of sqlite3.Connection object at 0x000001DF5C53A6B0>, 'INSERT INTO promo_codes (code, category, reward, expiration_time) VALUES (?, ?, ?, ?)', ('ADVANCED1', 'advanced', 350, '2024-10-01 17:39:56')) completed aiosqlite
2024-09-24 17:39:56,368 [INFO] Добавляем промокод: ADVANCED2, категория: advanced, награда: 400 root
2024-09-24 17:39:56,368 [DEBUG] executing functools.partial(<built-in method execute of sqlite3.Connection object at 0x000001DF5C53A6B0>, 'INSERT INTO promo_codes (code, category, reward, expiration_time) VALUES (?, ?, ?, ?)', ('ADVANCED2', 'advanced', 400, '2024-10-01 17:39:56')) aiosqlite
2024-09-24 17:39:56,368 [DEBUG] operation functools.partial(<built-in method execute of sqlite3.Connection object at 0x000001DF5C53A6B0>, 'INSERT INTO promo_codes (code, category, reward, expiration_time) VALUES (?, ?, ?, ?)', ('ADVANCED2', 'advanced', 400, '2024-10-01 17:39:56')) completed aiosqlite
2024-09-24 17:39:56,369 [INFO] Добавляем промокод: ADVANCED3, категория: advanced, награда: 450 root
2024-09-24 17:39:56,369 [DEBUG] executing functools.partial(<built-in method execute of sqlite3.Connection object at 0x000001DF5C53A6B0>, 'INSERT INTO promo_codes (code, category, reward, expiration_time) VALUES (?, ?, ?, ?)', ('ADVANCED3', 'advanced', 450, '2024-10-01 17:39:56')) aiosqlite
2024-09-24 17:39:56,369 [DEBUG] operation functools.partial(<built-in method execute of sqlite3.Connection object at 0x000001DF5C53A6B0>, 'INSERT INTO promo_codes (code, category, reward, expiration_time) VALUES (?, ?, ?, ?)', ('ADVANCED3', 'advanced', 450, '2024-10-01 17:39:56')) completed aiosqlite
2024-09-24 17:39:56,370 [DEBUG] executing functools.partial(<built-in method commit of sqlite3.Connection object at 0x000001DF5C53A6B0>) aiosqlite
2024-09-24 17:39:56,374 [DEBUG] operation functools.partial(<built-in method commit of sqlite3.Connection object at 0x000001DF5C53A6B0>) completed aiosqlite
2024-09-24 17:39:56,375 [INFO] Промокоды успешно вставлены в базу данных................................................................................................................. root
2024-09-24 17:39:56,375 [DEBUG] executing functools.partial(<built-in method close of sqlite3.Connection object at 0x000001DF5C53A6B0>) aiosqlite
2024-09-24 17:39:56,378 [DEBUG] operation functools.partial(<built-in method close of sqlite3.Connection object at 0x000001DF5C53A6B0>) completed aiosqlite
2024-09-24 17:39:56,381 [INFO] Бот успешно запущен... root
2024-09-24 17:39:56,381 [INFO] Start polling. aiogram.dispatcher.dispatcher
2024-09-24 17:39:56,382 [DEBUG] Make request: "deleteWebhook" with data: "{}" and files "None" aiogram
2024-09-24 17:40:07,648 [DEBUG] Response for deleteWebhook: [200] "'{"ok":true,"result":true,"description":"Webhook is already deleted"}'" aiogram
2024-09-24 17:40:07,649 [DEBUG] Make request: "getUpdates" with data: "{'timeout': 20}" and files "None" aiogram
2024-09-24 17:40:12,743 [DEBUG] Response for getUpdates: [409] "'{"ok":false,"error_code":409,"description":"Conflict: terminated by other getUpdates request; make sure that only one bot instance is running"}'" aiogram
2024-09-24 17:40:12,744 [ERROR] Cause exception while getting updates. aiogram.dispatcher.dispatcher
Traceback (most recent call last):
  File "C:\Users\Malam\AppData\Local\Packages\PythonSoftwareFoundation.Python.3.11_qbz5n2kfra8p0\LocalCache\local-packages\Python311\site-packages\aiogram\dispatcher\dispatcher.py", line 381, in start_polling
    updates = await self.bot.get_updates(
              ^^^^^^^^^^^^^^^^^^^^^^^^^^^
  File "C:\Users\Malam\AppData\Local\Packages\PythonSoftwareFoundation.Python.3.11_qbz5n2kfra8p0\LocalCache\local-packages\Python311\site-packages\aiogram\bot\bot.py", line 110, in get_updates
    result = await self.request(api.Methods.GET_UPDATES, payload)
             ^^^^^^^^^^^^^^^^^^^^^^^^^^^^^^^^^^^^^^^^^^^^^^^^^^^^
  File "C:\Users\Malam\AppData\Local\Packages\PythonSoftwareFoundation.Python.3.11_qbz5n2kfra8p0\LocalCache\local-packages\Python311\site-packages\aiogram\bot\base.py", line 236, in request
    return await api.make_request(await self.get_session(), self.server, self.__token, method, data, files,
           ^^^^^^^^^^^^^^^^^^^^^^^^^^^^^^^^^^^^^^^^^^^^^^^^^^^^^^^^^^^^^^^^^^^^^^^^^^^^^^^^^^^^^^^^^^^^^^^^
  File "C:\Users\Malam\AppData\Local\Packages\PythonSoftwareFoundation.Python.3.11_qbz5n2kfra8p0\LocalCache\local-packages\Python311\site-packages\aiogram\bot\api.py", line 140, in make_request
    return check_result(method, response.content_type, response.status, await response.text())
           ^^^^^^^^^^^^^^^^^^^^^^^^^^^^^^^^^^^^^^^^^^^^^^^^^^^^^^^^^^^^^^^^^^^^^^^^^^^^^^^^^^^
  File "C:\Users\Malam\AppData\Local\Packages\PythonSoftwareFoundation.Python.3.11_qbz5n2kfra8p0\LocalCache\local-packages\Python311\site-packages\aiogram\bot\api.py", line 119, in check_result
    exceptions.ConflictError.detect(description)
  File "C:\Users\Malam\AppData\Local\Packages\PythonSoftwareFoundation.Python.3.11_qbz5n2kfra8p0\LocalCache\local-packages\Python311\site-packages\aiogram\utils\exceptions.py", line 140, in detect
    raise err(cls.text or description)
aiogram.utils.exceptions.TerminatedByOtherGetUpdates: Terminated by other getupdates request; make sure that only one bot instance is running
2024-09-24 17:40:17,759 [DEBUG] Make request: "getUpdates" with data: "{'timeout': 20}" and files "None" aiogram
2024-09-24 17:40:22,867 [DEBUG] Response for getUpdates: [409] "'{"ok":false,"error_code":409,"description":"Conflict: terminated by other getUpdates request; make sure that only one bot instance is running"}'" aiogram
2024-09-24 17:40:22,867 [ERROR] Cause exception while getting updates. aiogram.dispatcher.dispatcher
Traceback (most recent call last):
  File "C:\Users\Malam\AppData\Local\Packages\PythonSoftwareFoundation.Python.3.11_qbz5n2kfra8p0\LocalCache\local-packages\Python311\site-packages\aiogram\dispatcher\dispatcher.py", line 381, in start_polling
    updates = await self.bot.get_updates(
              ^^^^^^^^^^^^^^^^^^^^^^^^^^^
  File "C:\Users\Malam\AppData\Local\Packages\PythonSoftwareFoundation.Python.3.11_qbz5n2kfra8p0\LocalCache\local-packages\Python311\site-packages\aiogram\bot\bot.py", line 110, in get_updates
    result = await self.request(api.Methods.GET_UPDATES, payload)
             ^^^^^^^^^^^^^^^^^^^^^^^^^^^^^^^^^^^^^^^^^^^^^^^^^^^^
  File "C:\Users\Malam\AppData\Local\Packages\PythonSoftwareFoundation.Python.3.11_qbz5n2kfra8p0\LocalCache\local-packages\Python311\site-packages\aiogram\bot\base.py", line 236, in request
    return await api.make_request(await self.get_session(), self.server, self.__token, method, data, files,
           ^^^^^^^^^^^^^^^^^^^^^^^^^^^^^^^^^^^^^^^^^^^^^^^^^^^^^^^^^^^^^^^^^^^^^^^^^^^^^^^^^^^^^^^^^^^^^^^^
  File "C:\Users\Malam\AppData\Local\Packages\PythonSoftwareFoundation.Python.3.11_qbz5n2kfra8p0\LocalCache\local-packages\Python311\site-packages\aiogram\bot\api.py", line 140, in make_request
    return check_result(method, response.content_type, response.status, await response.text())
           ^^^^^^^^^^^^^^^^^^^^^^^^^^^^^^^^^^^^^^^^^^^^^^^^^^^^^^^^^^^^^^^^^^^^^^^^^^^^^^^^^^^
  File "C:\Users\Malam\AppData\Local\Packages\PythonSoftwareFoundation.Python.3.11_qbz5n2kfra8p0\LocalCache\local-packages\Python311\site-packages\aiogram\bot\api.py", line 119, in check_result
    exceptions.ConflictError.detect(description)
  File "C:\Users\Malam\AppData\Local\Packages\PythonSoftwareFoundation.Python.3.11_qbz5n2kfra8p0\LocalCache\local-packages\Python311\site-packages\aiogram\utils\exceptions.py", line 140, in detect
    raise err(cls.text or description)
aiogram.utils.exceptions.TerminatedByOtherGetUpdates: Terminated by other getupdates request; make sure that only one bot instance is running
2024-09-24 17:40:27,879 [DEBUG] Make request: "getUpdates" with data: "{'timeout': 20}" and files "None" aiogram
2024-09-24 17:40:32,933 [WARNING] Polling is stopped. aiogram.dispatcher.dispatcher
2024-09-24 17:40:32,961 [INFO] Stop polling... aiogram.dispatcher.dispatcher
2024-09-24 17:40:32,962 [ERROR] Unclosed client session
client_session: <aiohttp.client.ClientSession object at 0x000001DF5C58E410> asyncio
2024-09-24 17:40:35,219 [DEBUG] Loaded middleware 'LoggingMiddleware' aiogram.Middleware
2024-09-24 17:40:35,221 [DEBUG] Using proactor: IocpProactor asyncio
2024-09-24 17:40:35,223 [INFO] Инициализация базы данных начата........................................................................................................................................ root
2024-09-24 17:40:35,224 [DEBUG] executing <function connect.<locals>.connector at 0x00000276C409C400> aiosqlite
2024-09-24 17:40:35,224 [DEBUG] operation <function connect.<locals>.connector at 0x00000276C409C400> completed aiosqlite
2024-09-24 17:40:35,225 [DEBUG] executing functools.partial(<built-in method execute of sqlite3.Connection object at 0x00000276C40466B0>, 'PRAGMA journal_mode=WAL;', []) aiosqlite
2024-09-24 17:40:35,226 [DEBUG] operation functools.partial(<built-in method execute of sqlite3.Connection object at 0x00000276C40466B0>, 'PRAGMA journal_mode=WAL;', []) completed aiosqlite
2024-09-24 17:40:35,227 [INFO] Таблица users создается root
2024-09-24 17:40:35,227 [DEBUG] executing functools.partial(<built-in method execute of sqlite3.Connection object at 0x00000276C40466B0>, '\n                CREATE TABLE IF NOT EXISTS users (\n                    user_id INTEGER PRIMARY KEY,\n                    username TEXT NOT NULL,\n                    balance REAL DEFAULT 0\n                )\n            ', []) aiosqlite
2024-09-24 17:40:35,232 [DEBUG] operation functools.partial(<built-in method execute of sqlite3.Connection object at 0x00000276C40466B0>, '\n                CREATE TABLE IF NOT EXISTS users (\n                    user_id INTEGER PRIMARY KEY,\n                    username TEXT NOT NULL,\n                    balance REAL DEFAULT 0\n                )\n            ', []) completed aiosqlite
2024-09-24 17:40:35,232 [INFO] Таблица users успешно создана или уже существует. root
2024-09-24 17:40:35,233 [INFO] Таблица cars создается root
2024-09-24 17:40:35,233 [DEBUG] executing functools.partial(<built-in method execute of sqlite3.Connection object at 0x00000276C40466B0>, '\n                CREATE TABLE IF NOT EXISTS cars (\n                    car_id INTEGER PRIMARY KEY,\n                    name TEXT NOT NULL,\n                    price REAL NOT NULL,\n                    power REAL NOT NULL,\n                    type TEXT NOT NULL\n                )\n            ', []) aiosqlite
2024-09-24 17:40:35,235 [DEBUG] operation functools.partial(<built-in method execute of sqlite3.Connection object at 0x00000276C40466B0>, '\n                CREATE TABLE IF NOT EXISTS cars (\n                    car_id INTEGER PRIMARY KEY,\n                    name TEXT NOT NULL,\n                    price REAL NOT NULL,\n                    power REAL NOT NULL,\n                    type TEXT NOT NULL\n                )\n            ', []) completed aiosqlite
2024-09-24 17:40:35,236 [INFO] Таблица cars успешно создана или уже существует. root
2024-09-24 17:40:35,236 [INFO] Таблица purchases создается root
2024-09-24 17:40:35,237 [DEBUG] executing functools.partial(<built-in method execute of sqlite3.Connection object at 0x00000276C40466B0>, '\n                CREATE TABLE IF NOT EXISTS purchases (\n                    user_id INTEGER,\n                    car_id INTEGER,\n                    purchase_date TEXT NOT NULL,\n                    FOREIGN KEY(user_id) REFERENCES users(user_id) ON DELETE CASCADE,\n                    FOREIGN KEY(car_id) REFERENCES cars(car_id) ON DELETE CASCADE\n                )\n            ', []) aiosqlite
2024-09-24 17:40:35,238 [DEBUG] operation functools.partial(<built-in method execute of sqlite3.Connection object at 0x00000276C40466B0>, '\n                CREATE TABLE IF NOT EXISTS purchases (\n                    user_id INTEGER,\n                    car_id INTEGER,\n                    purchase_date TEXT NOT NULL,\n                    FOREIGN KEY(user_id) REFERENCES users(user_id) ON DELETE CASCADE,\n                    FOREIGN KEY(car_id) REFERENCES cars(car_id) ON DELETE CASCADE\n                )\n            ', []) completed aiosqlite
2024-09-24 17:40:35,238 [INFO] Таблица purchases успешно создана или уже существует. root
2024-09-24 17:40:35,238 [INFO] Таблица earnings создается root
2024-09-24 17:40:35,238 [DEBUG] executing functools.partial(<built-in method execute of sqlite3.Connection object at 0x00000276C40466B0>, '\n                CREATE TABLE IF NOT EXISTS earnings (\n                    id INTEGER PRIMARY KEY AUTOINCREMENT,\n                    user_id INTEGER,\n                    amount REAL NOT NULL,\n                    timestamp TEXT NOT NULL,\n                    FOREIGN KEY(user_id) REFERENCES users(user_id) ON DELETE CASCADE\n                )\n            ', []) aiosqlite
2024-09-24 17:40:35,240 [DEBUG] operation functools.partial(<built-in method execute of sqlite3.Connection object at 0x00000276C40466B0>, '\n                CREATE TABLE IF NOT EXISTS earnings (\n                    id INTEGER PRIMARY KEY AUTOINCREMENT,\n                    user_id INTEGER,\n                    amount REAL NOT NULL,\n                    timestamp TEXT NOT NULL,\n                    FOREIGN KEY(user_id) REFERENCES users(user_id) ON DELETE CASCADE\n                )\n            ', []) completed aiosqlite
2024-09-24 17:40:35,242 [INFO] Таблица earnings успешно создана или уже существует. root
2024-09-24 17:40:35,242 [INFO] Таблица channels создается root
2024-09-24 17:40:35,242 [DEBUG] executing functools.partial(<built-in method execute of sqlite3.Connection object at 0x00000276C40466B0>, '\n                CREATE TABLE IF NOT EXISTS channels (\n                    id INTEGER PRIMARY KEY AUTOINCREMENT,\n                    name TEXT NOT NULL,\n                    link TEXT NOT NULL,\n                    promo_type TEXT NOT NULL\n                )\n            ', []) aiosqlite
2024-09-24 17:40:35,243 [DEBUG] operation functools.partial(<built-in method execute of sqlite3.Connection object at 0x00000276C40466B0>, '\n                CREATE TABLE IF NOT EXISTS channels (\n                    id INTEGER PRIMARY KEY AUTOINCREMENT,\n                    name TEXT NOT NULL,\n                    link TEXT NOT NULL,\n                    promo_type TEXT NOT NULL\n                )\n            ', []) completed aiosqlite
2024-09-24 17:40:35,245 [INFO] Таблица channels успешно создана или уже существует. root
2024-09-24 17:40:35,245 [INFO] Добавление данных в таблицу channels root
2024-09-24 17:40:35,245 [DEBUG] executing functools.partial(<built-in method execute of sqlite3.Connection object at 0x00000276C40466B0>, "\n                INSERT OR IGNORE INTO channels (name, link, promo_type) VALUES\n                ('Channel 1', 'https://t.me/channel1', 'regular'),\n                ('Channel 2', 'https://t.me/channel2', 'special'),\n                ('Channel 3', 'https://t.me/klev_ton', 'advanced')\n            ", []) aiosqlite
2024-09-24 17:40:35,245 [DEBUG] operation functools.partial(<built-in method execute of sqlite3.Connection object at 0x00000276C40466B0>, "\n                INSERT OR IGNORE INTO channels (name, link, promo_type) VALUES\n                ('Channel 1', 'https://t.me/channel1', 'regular'),\n                ('Channel 2', 'https://t.me/channel2', 'special'),\n                ('Channel 3', 'https://t.me/klev_ton', 'advanced')\n            ", []) completed aiosqlite
2024-09-24 17:40:35,246 [INFO] Данные в таблицу channels успешно добавлены. root
2024-09-24 17:40:35,246 [INFO] Таблица promo_codes создается root
2024-09-24 17:40:35,246 [DEBUG] executing functools.partial(<built-in method execute of sqlite3.Connection object at 0x00000276C40466B0>, '\n                CREATE TABLE IF NOT EXISTS promo_codes (\n                    id INTEGER PRIMARY KEY AUTOINCREMENT,\n                    code TEXT NOT NULL UNIQUE,\n                    category TEXT NOT NULL,\n                    reward INTEGER NOT NULL,\n                    expiration_time TEXT NOT NULL\n                )\n            ', []) aiosqlite
2024-09-24 17:40:35,247 [DEBUG] operation functools.partial(<built-in method execute of sqlite3.Connection object at 0x00000276C40466B0>, '\n                CREATE TABLE IF NOT EXISTS promo_codes (\n                    id INTEGER PRIMARY KEY AUTOINCREMENT,\n                    code TEXT NOT NULL UNIQUE,\n                    category TEXT NOT NULL,\n                    reward INTEGER NOT NULL,\n                    expiration_time TEXT NOT NULL\n                )\n            ', []) completed aiosqlite
2024-09-24 17:40:35,248 [INFO] Таблица promo_codes успешно создана или уже существует. root
2024-09-24 17:40:35,248 [DEBUG] executing functools.partial(<built-in method commit of sqlite3.Connection object at 0x00000276C40466B0>) aiosqlite
2024-09-24 17:40:35,250 [DEBUG] operation functools.partial(<built-in method commit of sqlite3.Connection object at 0x00000276C40466B0>) completed aiosqlite
2024-09-24 17:40:35,251 [DEBUG] executing functools.partial(<built-in method close of sqlite3.Connection object at 0x00000276C40466B0>) aiosqlite
2024-09-24 17:40:35,254 [DEBUG] operation functools.partial(<built-in method close of sqlite3.Connection object at 0x00000276C40466B0>) completed aiosqlite
2024-09-24 17:40:35,255 [INFO] Инициализация базы данных завершена. root
2024-09-24 17:40:35,257 [DEBUG] executing <function connect.<locals>.connector at 0x00000276C409C400> aiosqlite
2024-09-24 17:40:35,258 [DEBUG] operation <function connect.<locals>.connector at 0x00000276C409C400> completed aiosqlite
2024-09-24 17:40:35,260 [DEBUG] executing functools.partial(<built-in method cursor of sqlite3.Connection object at 0x00000276C40466B0>) aiosqlite
2024-09-24 17:40:35,261 [DEBUG] operation functools.partial(<built-in method cursor of sqlite3.Connection object at 0x00000276C40466B0>) completed aiosqlite
2024-09-24 17:40:35,261 [DEBUG] executing functools.partial(<built-in method execute of sqlite3.Cursor object at 0x00000276C403FD40>, "SELECT name FROM sqlite_master WHERE type='table';", []) aiosqlite
2024-09-24 17:40:35,264 [DEBUG] operation functools.partial(<built-in method execute of sqlite3.Cursor object at 0x00000276C403FD40>, "SELECT name FROM sqlite_master WHERE type='table';", []) completed aiosqlite
2024-09-24 17:40:35,265 [DEBUG] executing functools.partial(<built-in method fetchall of sqlite3.Cursor object at 0x00000276C403FD40>) aiosqlite
2024-09-24 17:40:35,266 [DEBUG] operation functools.partial(<built-in method fetchall of sqlite3.Cursor object at 0x00000276C403FD40>) completed aiosqlite
2024-09-24 17:40:35,267 [INFO] Таблицы в базе данных: [('users',), ('cars',), ('purchases',), ('earnings',), ('sqlite_sequence',), ('channels',), ('promo_codes',)] root
2024-09-24 17:40:35,268 [DEBUG] executing functools.partial(<built-in method close of sqlite3.Cursor object at 0x00000276C403FD40>) aiosqlite
2024-09-24 17:40:35,268 [DEBUG] operation functools.partial(<built-in method close of sqlite3.Cursor object at 0x00000276C403FD40>) completed aiosqlite
2024-09-24 17:40:35,269 [DEBUG] executing functools.partial(<built-in method close of sqlite3.Connection object at 0x00000276C40466B0>) aiosqlite
2024-09-24 17:40:35,270 [DEBUG] operation functools.partial(<built-in method close of sqlite3.Connection object at 0x00000276C40466B0>) completed aiosqlite
2024-09-24 17:40:35,274 [DEBUG] executing <function connect.<locals>.connector at 0x00000276C409C720> aiosqlite
2024-09-24 17:40:35,276 [DEBUG] operation <function connect.<locals>.connector at 0x00000276C409C720> completed aiosqlite
2024-09-24 17:40:35,277 [INFO] Вставка заранее подготовленных промокодов в базу данных.......................................................................................................... root
2024-09-24 17:40:35,277 [DEBUG] executing functools.partial(<built-in method execute of sqlite3.Connection object at 0x00000276C40466B0>, 'DELETE FROM promo_codes', []) aiosqlite
2024-09-24 17:40:35,282 [DEBUG] operation functools.partial(<built-in method execute of sqlite3.Connection object at 0x00000276C40466B0>, 'DELETE FROM promo_codes', []) completed aiosqlite
2024-09-24 17:40:35,284 [INFO] Добавляем промокод: CODE1, категория: normal, награда: 10 root
2024-09-24 17:40:35,285 [DEBUG] executing functools.partial(<built-in method execute of sqlite3.Connection object at 0x00000276C40466B0>, 'INSERT INTO promo_codes (code, category, reward, expiration_time) VALUES (?, ?, ?, ?)', ('CODE1', 'normal', 10, '2024-10-01 17:40:35')) aiosqlite
2024-09-24 17:40:35,286 [DEBUG] operation functools.partial(<built-in method execute of sqlite3.Connection object at 0x00000276C40466B0>, 'INSERT INTO promo_codes (code, category, reward, expiration_time) VALUES (?, ?, ?, ?)', ('CODE1', 'normal', 10, '2024-10-01 17:40:35')) completed aiosqlite
2024-09-24 17:40:35,288 [INFO] Добавляем промокод: CODE2, категория: normal, награда: 10 root
2024-09-24 17:40:35,288 [DEBUG] executing functools.partial(<built-in method execute of sqlite3.Connection object at 0x00000276C40466B0>, 'INSERT INTO promo_codes (code, category, reward, expiration_time) VALUES (?, ?, ?, ?)', ('CODE2', 'normal', 10, '2024-10-01 17:40:35')) aiosqlite
2024-09-24 17:40:35,289 [DEBUG] operation functools.partial(<built-in method execute of sqlite3.Connection object at 0x00000276C40466B0>, 'INSERT INTO promo_codes (code, category, reward, expiration_time) VALUES (?, ?, ?, ?)', ('CODE2', 'normal', 10, '2024-10-01 17:40:35')) completed aiosqlite
2024-09-24 17:40:35,289 [INFO] Добавляем промокод: CODE3, категория: normal, награда: 10 root
2024-09-24 17:40:35,290 [DEBUG] executing functools.partial(<built-in method execute of sqlite3.Connection object at 0x00000276C40466B0>, 'INSERT INTO promo_codes (code, category, reward, expiration_time) VALUES (?, ?, ?, ?)', ('CODE3', 'normal', 10, '2024-10-01 17:40:35')) aiosqlite
2024-09-24 17:40:35,290 [DEBUG] operation functools.partial(<built-in method execute of sqlite3.Connection object at 0x00000276C40466B0>, 'INSERT INTO promo_codes (code, category, reward, expiration_time) VALUES (?, ?, ?, ?)', ('CODE3', 'normal', 10, '2024-10-01 17:40:35')) completed aiosqlite
2024-09-24 17:40:35,291 [INFO] Добавляем промокод: CODE4, категория: normal, награда: 30 root
2024-09-24 17:40:35,291 [DEBUG] executing functools.partial(<built-in method execute of sqlite3.Connection object at 0x00000276C40466B0>, 'INSERT INTO promo_codes (code, category, reward, expiration_time) VALUES (?, ?, ?, ?)', ('CODE4', 'normal', 30, '2024-10-01 17:40:35')) aiosqlite
2024-09-24 17:40:35,291 [DEBUG] operation functools.partial(<built-in method execute of sqlite3.Connection object at 0x00000276C40466B0>, 'INSERT INTO promo_codes (code, category, reward, expiration_time) VALUES (?, ?, ?, ?)', ('CODE4', 'normal', 30, '2024-10-01 17:40:35')) completed aiosqlite
2024-09-24 17:40:35,292 [INFO] Добавляем промокод: CODE5, категория: normal, награда: 30 root
2024-09-24 17:40:35,292 [DEBUG] executing functools.partial(<built-in method execute of sqlite3.Connection object at 0x00000276C40466B0>, 'INSERT INTO promo_codes (code, category, reward, expiration_time) VALUES (?, ?, ?, ?)', ('CODE5', 'normal', 30, '2024-10-01 17:40:35')) aiosqlite
2024-09-24 17:40:35,292 [DEBUG] operation functools.partial(<built-in method execute of sqlite3.Connection object at 0x00000276C40466B0>, 'INSERT INTO promo_codes (code, category, reward, expiration_time) VALUES (?, ?, ?, ?)', ('CODE5', 'normal', 30, '2024-10-01 17:40:35')) completed aiosqlite
2024-09-24 17:40:35,293 [INFO] Добавляем промокод: CODE6, категория: normal, награда: 50 root
2024-09-24 17:40:35,293 [DEBUG] executing functools.partial(<built-in method execute of sqlite3.Connection object at 0x00000276C40466B0>, 'INSERT INTO promo_codes (code, category, reward, expiration_time) VALUES (?, ?, ?, ?)', ('CODE6', 'normal', 50, '2024-10-01 17:40:35')) aiosqlite
2024-09-24 17:40:35,293 [DEBUG] operation functools.partial(<built-in method execute of sqlite3.Connection object at 0x00000276C40466B0>, 'INSERT INTO promo_codes (code, category, reward, expiration_time) VALUES (?, ?, ?, ?)', ('CODE6', 'normal', 50, '2024-10-01 17:40:35')) completed aiosqlite
2024-09-24 17:40:35,294 [INFO] Добавляем промокод: SPECIAL1, категория: special, награда: 100 root
2024-09-24 17:40:35,294 [DEBUG] executing functools.partial(<built-in method execute of sqlite3.Connection object at 0x00000276C40466B0>, 'INSERT INTO promo_codes (code, category, reward, expiration_time) VALUES (?, ?, ?, ?)', ('SPECIAL1', 'special', 100, '2024-10-01 17:40:35')) aiosqlite
2024-09-24 17:40:35,294 [DEBUG] operation functools.partial(<built-in method execute of sqlite3.Connection object at 0x00000276C40466B0>, 'INSERT INTO promo_codes (code, category, reward, expiration_time) VALUES (?, ?, ?, ?)', ('SPECIAL1', 'special', 100, '2024-10-01 17:40:35')) completed aiosqlite
2024-09-24 17:40:35,295 [INFO] Добавляем промокод: SPECIAL2, категория: special, награда: 150 root
2024-09-24 17:40:35,296 [DEBUG] executing functools.partial(<built-in method execute of sqlite3.Connection object at 0x00000276C40466B0>, 'INSERT INTO promo_codes (code, category, reward, expiration_time) VALUES (?, ?, ?, ?)', ('SPECIAL2', 'special', 150, '2024-10-01 17:40:35')) aiosqlite
2024-09-24 17:40:35,296 [DEBUG] operation functools.partial(<built-in method execute of sqlite3.Connection object at 0x00000276C40466B0>, 'INSERT INTO promo_codes (code, category, reward, expiration_time) VALUES (?, ?, ?, ?)', ('SPECIAL2', 'special', 150, '2024-10-01 17:40:35')) completed aiosqlite
2024-09-24 17:40:35,297 [INFO] Добавляем промокод: SPECIAL3, категория: special, награда: 200 root
2024-09-24 17:40:35,298 [DEBUG] executing functools.partial(<built-in method execute of sqlite3.Connection object at 0x00000276C40466B0>, 'INSERT INTO promo_codes (code, category, reward, expiration_time) VALUES (?, ?, ?, ?)', ('SPECIAL3', 'special', 200, '2024-10-01 17:40:35')) aiosqlite
2024-09-24 17:40:35,299 [DEBUG] operation functools.partial(<built-in method execute of sqlite3.Connection object at 0x00000276C40466B0>, 'INSERT INTO promo_codes (code, category, reward, expiration_time) VALUES (?, ?, ?, ?)', ('SPECIAL3', 'special', 200, '2024-10-01 17:40:35')) completed aiosqlite
2024-09-24 17:40:35,299 [INFO] Добавляем промокод: ADVANCED1, категория: advanced, награда: 350 root
2024-09-24 17:40:35,299 [DEBUG] executing functools.partial(<built-in method execute of sqlite3.Connection object at 0x00000276C40466B0>, 'INSERT INTO promo_codes (code, category, reward, expiration_time) VALUES (?, ?, ?, ?)', ('ADVANCED1', 'advanced', 350, '2024-10-01 17:40:35')) aiosqlite
2024-09-24 17:40:35,300 [DEBUG] operation functools.partial(<built-in method execute of sqlite3.Connection object at 0x00000276C40466B0>, 'INSERT INTO promo_codes (code, category, reward, expiration_time) VALUES (?, ?, ?, ?)', ('ADVANCED1', 'advanced', 350, '2024-10-01 17:40:35')) completed aiosqlite
2024-09-24 17:40:35,300 [INFO] Добавляем промокод: ADVANCED2, категория: advanced, награда: 400 root
2024-09-24 17:40:35,300 [DEBUG] executing functools.partial(<built-in method execute of sqlite3.Connection object at 0x00000276C40466B0>, 'INSERT INTO promo_codes (code, category, reward, expiration_time) VALUES (?, ?, ?, ?)', ('ADVANCED2', 'advanced', 400, '2024-10-01 17:40:35')) aiosqlite
2024-09-24 17:40:35,300 [DEBUG] operation functools.partial(<built-in method execute of sqlite3.Connection object at 0x00000276C40466B0>, 'INSERT INTO promo_codes (code, category, reward, expiration_time) VALUES (?, ?, ?, ?)', ('ADVANCED2', 'advanced', 400, '2024-10-01 17:40:35')) completed aiosqlite
2024-09-24 17:40:35,301 [INFO] Добавляем промокод: ADVANCED3, категория: advanced, награда: 450 root
2024-09-24 17:40:35,301 [DEBUG] executing functools.partial(<built-in method execute of sqlite3.Connection object at 0x00000276C40466B0>, 'INSERT INTO promo_codes (code, category, reward, expiration_time) VALUES (?, ?, ?, ?)', ('ADVANCED3', 'advanced', 450, '2024-10-01 17:40:35')) aiosqlite
2024-09-24 17:40:35,302 [DEBUG] operation functools.partial(<built-in method execute of sqlite3.Connection object at 0x00000276C40466B0>, 'INSERT INTO promo_codes (code, category, reward, expiration_time) VALUES (?, ?, ?, ?)', ('ADVANCED3', 'advanced', 450, '2024-10-01 17:40:35')) completed aiosqlite
2024-09-24 17:40:35,303 [DEBUG] executing functools.partial(<built-in method commit of sqlite3.Connection object at 0x00000276C40466B0>) aiosqlite
2024-09-24 17:40:35,308 [DEBUG] operation functools.partial(<built-in method commit of sqlite3.Connection object at 0x00000276C40466B0>) completed aiosqlite
2024-09-24 17:40:35,309 [INFO] Промокоды успешно вставлены в базу данных................................................................................................................. root
2024-09-24 17:40:35,310 [DEBUG] executing functools.partial(<built-in method close of sqlite3.Connection object at 0x00000276C40466B0>) aiosqlite
2024-09-24 17:40:35,314 [DEBUG] operation functools.partial(<built-in method close of sqlite3.Connection object at 0x00000276C40466B0>) completed aiosqlite
2024-09-24 17:40:35,314 [INFO] Бот успешно запущен... root
2024-09-24 17:40:35,315 [INFO] Start polling. aiogram.dispatcher.dispatcher
2024-09-24 17:40:35,315 [DEBUG] Make request: "deleteWebhook" with data: "{}" and files "None" aiogram
2024-09-24 17:40:46,543 [DEBUG] Response for deleteWebhook: [200] "'{"ok":true,"result":true,"description":"Webhook is already deleted"}'" aiogram
2024-09-24 17:40:46,544 [DEBUG] Make request: "getUpdates" with data: "{'timeout': 20}" and files "None" aiogram
2024-09-24 17:40:51,606 [DEBUG] Response for getUpdates: [409] "'{"ok":false,"error_code":409,"description":"Conflict: terminated by other getUpdates request; make sure that only one bot instance is running"}'" aiogram
2024-09-24 17:40:51,607 [ERROR] Cause exception while getting updates. aiogram.dispatcher.dispatcher
Traceback (most recent call last):
  File "C:\Users\Malam\AppData\Local\Packages\PythonSoftwareFoundation.Python.3.11_qbz5n2kfra8p0\LocalCache\local-packages\Python311\site-packages\aiogram\dispatcher\dispatcher.py", line 381, in start_polling
    updates = await self.bot.get_updates(
              ^^^^^^^^^^^^^^^^^^^^^^^^^^^
  File "C:\Users\Malam\AppData\Local\Packages\PythonSoftwareFoundation.Python.3.11_qbz5n2kfra8p0\LocalCache\local-packages\Python311\site-packages\aiogram\bot\bot.py", line 110, in get_updates
    result = await self.request(api.Methods.GET_UPDATES, payload)
             ^^^^^^^^^^^^^^^^^^^^^^^^^^^^^^^^^^^^^^^^^^^^^^^^^^^^
  File "C:\Users\Malam\AppData\Local\Packages\PythonSoftwareFoundation.Python.3.11_qbz5n2kfra8p0\LocalCache\local-packages\Python311\site-packages\aiogram\bot\base.py", line 236, in request
    return await api.make_request(await self.get_session(), self.server, self.__token, method, data, files,
           ^^^^^^^^^^^^^^^^^^^^^^^^^^^^^^^^^^^^^^^^^^^^^^^^^^^^^^^^^^^^^^^^^^^^^^^^^^^^^^^^^^^^^^^^^^^^^^^^
  File "C:\Users\Malam\AppData\Local\Packages\PythonSoftwareFoundation.Python.3.11_qbz5n2kfra8p0\LocalCache\local-packages\Python311\site-packages\aiogram\bot\api.py", line 140, in make_request
    return check_result(method, response.content_type, response.status, await response.text())
           ^^^^^^^^^^^^^^^^^^^^^^^^^^^^^^^^^^^^^^^^^^^^^^^^^^^^^^^^^^^^^^^^^^^^^^^^^^^^^^^^^^^
  File "C:\Users\Malam\AppData\Local\Packages\PythonSoftwareFoundation.Python.3.11_qbz5n2kfra8p0\LocalCache\local-packages\Python311\site-packages\aiogram\bot\api.py", line 119, in check_result
    exceptions.ConflictError.detect(description)
  File "C:\Users\Malam\AppData\Local\Packages\PythonSoftwareFoundation.Python.3.11_qbz5n2kfra8p0\LocalCache\local-packages\Python311\site-packages\aiogram\utils\exceptions.py", line 140, in detect
    raise err(cls.text or description)
aiogram.utils.exceptions.TerminatedByOtherGetUpdates: Terminated by other getupdates request; make sure that only one bot instance is running
2024-09-24 17:40:56,619 [DEBUG] Make request: "getUpdates" with data: "{'timeout': 20}" and files "None" aiogram
2024-09-24 17:40:56,953 [WARNING] Polling is stopped. aiogram.dispatcher.dispatcher
2024-09-24 17:40:56,968 [INFO] Stop polling... aiogram.dispatcher.dispatcher
2024-09-24 17:40:56,970 [ERROR] Unclosed client session
client_session: <aiohttp.client.ClientSession object at 0x00000276C408F4D0> asyncio
